[2025-03-03T12:32:01.704454+01:00] request.INFO: Matched route "api_login". {"route":"api_login","route_parameters":{"_route":"api_login","_controller":"App\\Controller\\SecurityController::login"},"request_uri":"http://localhost/api/login_check","method":"POST"} []
[2025-03-03T12:32:01.772692+01:00] security.DEBUG: Checking for authenticator support. {"firewall_name":"login","authenticators":1} []
[2025-03-03T12:32:01.772702+01:00] security.DEBUG: Checking support on authenticator. {"firewall_name":"login","authenticator":"Symfony\\Component\\Security\\Http\\Authenticator\\Debug\\TraceableAuthenticator"} []
[2025-03-03T12:32:01.783023+01:00] request.ERROR: Uncaught PHP Exception Symfony\Component\HttpKernel\Exception\BadRequestHttpException: "The key "email" must be provided." at JsonLoginAuthenticator.php line 153 {"exception":"[object] (Symfony\\Component\\HttpKernel\\Exception\\BadRequestHttpException(code: 0): The key \"email\" must be provided. at C:\\Users\\CDAX27\\covoiturage\\vendor\\symfony\\security-http\\Authenticator\\JsonLoginAuthenticator.php:153)\n[previous exception] [object] (Symfony\\Component\\PropertyAccess\\Exception\\NoSuchPropertyException(code: 0): Can't get a way to read the property \"email\" in class \"stdClass\". at C:\\Users\\CDAX27\\covoiturage\\vendor\\symfony\\property-access\\PropertyAccessor.php:456)"} []
[2025-03-03T14:15:35.522722+01:00] request.INFO: Matched route "api_login". {"route":"api_login","route_parameters":{"_route":"api_login","_controller":"App\\Controller\\SecurityController::login"},"request_uri":"http://localhost/api/login_check","method":"POST"} []
[2025-03-03T14:15:35.588463+01:00] security.DEBUG: Checking for authenticator support. {"firewall_name":"login","authenticators":1} []
[2025-03-03T14:15:35.588474+01:00] security.DEBUG: Checking support on authenticator. {"firewall_name":"login","authenticator":"Symfony\\Component\\Security\\Http\\Authenticator\\Debug\\TraceableAuthenticator"} []
[2025-03-03T14:15:35.597824+01:00] request.ERROR: Uncaught PHP Exception Symfony\Component\HttpKernel\Exception\BadRequestHttpException: "The key "email" must be provided." at JsonLoginAuthenticator.php line 153 {"exception":"[object] (Symfony\\Component\\HttpKernel\\Exception\\BadRequestHttpException(code: 0): The key \"email\" must be provided. at C:\\Users\\CDAX27\\covoiturage\\vendor\\symfony\\security-http\\Authenticator\\JsonLoginAuthenticator.php:153)\n[previous exception] [object] (Symfony\\Component\\PropertyAccess\\Exception\\NoSuchPropertyException(code: 0): Can't get a way to read the property \"email\" in class \"stdClass\". at C:\\Users\\CDAX27\\covoiturage\\vendor\\symfony\\property-access\\PropertyAccessor.php:456)"} []
[2025-03-03T14:24:20.429384+01:00] request.INFO: Matched route "api_login". {"route":"api_login","route_parameters":{"_route":"api_login","_controller":"App\\Controller\\SecurityController::login"},"request_uri":"http://localhost/api/login_check","method":"POST"} []
[2025-03-03T14:24:20.530492+01:00] security.DEBUG: Checking for authenticator support. {"firewall_name":"login","authenticators":1} []
[2025-03-03T14:24:20.530512+01:00] security.DEBUG: Checking support on authenticator. {"firewall_name":"login","authenticator":"Symfony\\Component\\Security\\Http\\Authenticator\\Debug\\TraceableAuthenticator"} []
[2025-03-03T14:24:20.753551+01:00] doctrine.INFO: Connecting with parameters array{"use_savepoints":true,"dbname_suffix":"_test","driver":"pdo_mysql","idle_connection_ttl":600,"host":"mysql","port":3306,"user":"user","password":"<redacted>","driverOptions":[],"defaultTableOptions":[],"dbname":"db_test","charset":"utf8mb4","serverVersion":"10.6.21-MariaDB"} {"params":{"use_savepoints":true,"dbname_suffix":"_test","driver":"pdo_mysql","idle_connection_ttl":600,"host":"mysql","port":3306,"user":"user","password":"<redacted>","driverOptions":[],"defaultTableOptions":[],"dbname":"db_test","charset":"utf8mb4","serverVersion":"10.6.21-MariaDB"}} []
[2025-03-03T14:24:23.505782+01:00] request.CRITICAL: Uncaught PHP Exception Doctrine\DBAL\Exception\ConnectionException: "An exception occurred in the driver: SQLSTATE[HY000] [2002] php_network_getaddresses: getaddrinfo for mysql failed: Hôte inconnu. " at ExceptionConverter.php line 101 {"exception":"[object] (Doctrine\\DBAL\\Exception\\ConnectionException(code: 2002): An exception occurred in the driver: SQLSTATE[HY000] [2002] php_network_getaddresses: getaddrinfo for mysql failed: Hï¿½te inconnu.  at C:\\Users\\CDAX27\\covoiturage\\vendor\\doctrine\\dbal\\src\\Driver\\API\\MySQL\\ExceptionConverter.php:101)\n[previous exception] [object] (Doctrine\\DBAL\\Driver\\PDO\\Exception(code: 2002): SQLSTATE[HY000] [2002] php_network_getaddresses: getaddrinfo for mysql failed: Hï¿½te inconnu.  at C:\\Users\\CDAX27\\covoiturage\\vendor\\doctrine\\dbal\\src\\Driver\\PDO\\Exception.php:24)\n[previous exception] [object] (PDOException(code: 2002): SQLSTATE[HY000] [2002] php_network_getaddresses: getaddrinfo for mysql failed: Hï¿½te inconnu.  at C:\\Users\\CDAX27\\covoiturage\\vendor\\doctrine\\dbal\\src\\Driver\\PDO\\MySQL\\Driver.php:33)\n[previous exception] [object] (PDOException(code: 0): PDO::__construct(): php_network_getaddresses: getaddrinfo for mysql failed: Hï¿½te inconnu.  at C:\\Users\\CDAX27\\covoiturage\\vendor\\doctrine\\dbal\\src\\Driver\\PDO\\MySQL\\Driver.php:33)"} []
[2025-03-03T14:39:16.321404+01:00] request.INFO: Matched route "api_login". {"route":"api_login","route_parameters":{"_route":"api_login","_controller":"App\\Controller\\SecurityController::login"},"request_uri":"http://localhost/api/login_check","method":"POST"} []
[2025-03-03T14:39:16.382961+01:00] security.DEBUG: Checking for authenticator support. {"firewall_name":"login","authenticators":1} []
[2025-03-03T14:39:16.382973+01:00] security.DEBUG: Checking support on authenticator. {"firewall_name":"login","authenticator":"Symfony\\Component\\Security\\Http\\Authenticator\\Debug\\TraceableAuthenticator"} []
[2025-03-03T14:39:16.547906+01:00] doctrine.INFO: Connecting with parameters array{"use_savepoints":true,"dbname_suffix":"_test","driver":"pdo_mysql","idle_connection_ttl":600,"host":"mysql","port":3306,"user":"user","password":"<redacted>","driverOptions":[],"defaultTableOptions":[],"dbname":"db_test","charset":"utf8mb4","serverVersion":"10.6.21-MariaDB"} {"params":{"use_savepoints":true,"dbname_suffix":"_test","driver":"pdo_mysql","idle_connection_ttl":600,"host":"mysql","port":3306,"user":"user","password":"<redacted>","driverOptions":[],"defaultTableOptions":[],"dbname":"db_test","charset":"utf8mb4","serverVersion":"10.6.21-MariaDB"}} []
[2025-03-03T14:39:19.316837+01:00] request.CRITICAL: Uncaught PHP Exception Doctrine\DBAL\Exception\ConnectionException: "An exception occurred in the driver: SQLSTATE[HY000] [2002] php_network_getaddresses: getaddrinfo for mysql failed: Hôte inconnu. " at ExceptionConverter.php line 101 {"exception":"[object] (Doctrine\\DBAL\\Exception\\ConnectionException(code: 2002): An exception occurred in the driver: SQLSTATE[HY000] [2002] php_network_getaddresses: getaddrinfo for mysql failed: Hï¿½te inconnu.  at C:\\Users\\CDAX27\\covoiturage\\vendor\\doctrine\\dbal\\src\\Driver\\API\\MySQL\\ExceptionConverter.php:101)\n[previous exception] [object] (Doctrine\\DBAL\\Driver\\PDO\\Exception(code: 2002): SQLSTATE[HY000] [2002] php_network_getaddresses: getaddrinfo for mysql failed: Hï¿½te inconnu.  at C:\\Users\\CDAX27\\covoiturage\\vendor\\doctrine\\dbal\\src\\Driver\\PDO\\Exception.php:24)\n[previous exception] [object] (PDOException(code: 2002): SQLSTATE[HY000] [2002] php_network_getaddresses: getaddrinfo for mysql failed: Hï¿½te inconnu.  at C:\\Users\\CDAX27\\covoiturage\\vendor\\doctrine\\dbal\\src\\Driver\\PDO\\MySQL\\Driver.php:33)\n[previous exception] [object] (PDOException(code: 0): PDO::__construct(): php_network_getaddresses: getaddrinfo for mysql failed: Hï¿½te inconnu.  at C:\\Users\\CDAX27\\covoiturage\\vendor\\doctrine\\dbal\\src\\Driver\\PDO\\MySQL\\Driver.php:33)"} []
[2025-03-03T14:41:15.808967+01:00] request.INFO: Matched route "api_login". {"route":"api_login","route_parameters":{"_route":"api_login","_controller":"App\\Controller\\SecurityController::login"},"request_uri":"http://localhost/api/login_check","method":"POST"} []
[2025-03-03T14:41:15.860519+01:00] security.DEBUG: Checking for authenticator support. {"firewall_name":"login","authenticators":1} []
[2025-03-03T14:41:15.860528+01:00] security.DEBUG: Checking support on authenticator. {"firewall_name":"login","authenticator":"Symfony\\Component\\Security\\Http\\Authenticator\\Debug\\TraceableAuthenticator"} []
[2025-03-03T14:41:15.988598+01:00] doctrine.INFO: Connecting with parameters array{"use_savepoints":true,"dbname_suffix":"_test","driver":"pdo_mysql","idle_connection_ttl":600,"host":"mysql","port":3306,"user":"user","password":"<redacted>","driverOptions":[],"defaultTableOptions":[],"dbname":"db_test","charset":"utf8mb4","serverVersion":"10.6.21-MariaDB"} {"params":{"use_savepoints":true,"dbname_suffix":"_test","driver":"pdo_mysql","idle_connection_ttl":600,"host":"mysql","port":3306,"user":"user","password":"<redacted>","driverOptions":[],"defaultTableOptions":[],"dbname":"db_test","charset":"utf8mb4","serverVersion":"10.6.21-MariaDB"}} []
[2025-03-03T14:41:18.760204+01:00] request.CRITICAL: Uncaught PHP Exception Doctrine\DBAL\Exception\ConnectionException: "An exception occurred in the driver: SQLSTATE[HY000] [2002] php_network_getaddresses: getaddrinfo for mysql failed: Hôte inconnu. " at ExceptionConverter.php line 101 {"exception":"[object] (Doctrine\\DBAL\\Exception\\ConnectionException(code: 2002): An exception occurred in the driver: SQLSTATE[HY000] [2002] php_network_getaddresses: getaddrinfo for mysql failed: Hï¿½te inconnu.  at C:\\Users\\CDAX27\\covoiturage\\vendor\\doctrine\\dbal\\src\\Driver\\API\\MySQL\\ExceptionConverter.php:101)\n[previous exception] [object] (Doctrine\\DBAL\\Driver\\PDO\\Exception(code: 2002): SQLSTATE[HY000] [2002] php_network_getaddresses: getaddrinfo for mysql failed: Hï¿½te inconnu.  at C:\\Users\\CDAX27\\covoiturage\\vendor\\doctrine\\dbal\\src\\Driver\\PDO\\Exception.php:24)\n[previous exception] [object] (PDOException(code: 2002): SQLSTATE[HY000] [2002] php_network_getaddresses: getaddrinfo for mysql failed: Hï¿½te inconnu.  at C:\\Users\\CDAX27\\covoiturage\\vendor\\doctrine\\dbal\\src\\Driver\\PDO\\MySQL\\Driver.php:33)\n[previous exception] [object] (PDOException(code: 0): PDO::__construct(): php_network_getaddresses: getaddrinfo for mysql failed: Hï¿½te inconnu.  at C:\\Users\\CDAX27\\covoiturage\\vendor\\doctrine\\dbal\\src\\Driver\\PDO\\MySQL\\Driver.php:33)"} []
[2025-03-03T14:47:40.632669+01:00] request.INFO: Matched route "api_login". {"route":"api_login","route_parameters":{"_route":"api_login","_controller":"App\\Controller\\SecurityController::login"},"request_uri":"http://localhost/api/login_check","method":"POST"} []
[2025-03-03T14:47:40.701005+01:00] security.DEBUG: Checking for authenticator support. {"firewall_name":"login","authenticators":1} []
[2025-03-03T14:47:40.701018+01:00] security.DEBUG: Checking support on authenticator. {"firewall_name":"login","authenticator":"Symfony\\Component\\Security\\Http\\Authenticator\\Debug\\TraceableAuthenticator"} []
[2025-03-03T14:47:40.850253+01:00] doctrine.INFO: Connecting with parameters array{"use_savepoints":true,"dbname_suffix":"_test","driver":"pdo_mysql","idle_connection_ttl":600,"host":"mysql","port":3306,"user":"user","password":"<redacted>","driverOptions":[],"defaultTableOptions":[],"dbname":"db_test","charset":"utf8mb4","serverVersion":"10.6.21-MariaDB"} {"params":{"use_savepoints":true,"dbname_suffix":"_test","driver":"pdo_mysql","idle_connection_ttl":600,"host":"mysql","port":3306,"user":"user","password":"<redacted>","driverOptions":[],"defaultTableOptions":[],"dbname":"db_test","charset":"utf8mb4","serverVersion":"10.6.21-MariaDB"}} []
[2025-03-03T14:47:43.596970+01:00] request.CRITICAL: Uncaught PHP Exception Doctrine\DBAL\Exception\ConnectionException: "An exception occurred in the driver: SQLSTATE[HY000] [2002] php_network_getaddresses: getaddrinfo for mysql failed: Hôte inconnu. " at ExceptionConverter.php line 101 {"exception":"[object] (Doctrine\\DBAL\\Exception\\ConnectionException(code: 2002): An exception occurred in the driver: SQLSTATE[HY000] [2002] php_network_getaddresses: getaddrinfo for mysql failed: Hï¿½te inconnu.  at C:\\Users\\CDAX27\\covoiturage\\vendor\\doctrine\\dbal\\src\\Driver\\API\\MySQL\\ExceptionConverter.php:101)\n[previous exception] [object] (Doctrine\\DBAL\\Driver\\PDO\\Exception(code: 2002): SQLSTATE[HY000] [2002] php_network_getaddresses: getaddrinfo for mysql failed: Hï¿½te inconnu.  at C:\\Users\\CDAX27\\covoiturage\\vendor\\doctrine\\dbal\\src\\Driver\\PDO\\Exception.php:24)\n[previous exception] [object] (PDOException(code: 2002): SQLSTATE[HY000] [2002] php_network_getaddresses: getaddrinfo for mysql failed: Hï¿½te inconnu.  at C:\\Users\\CDAX27\\covoiturage\\vendor\\doctrine\\dbal\\src\\Driver\\PDO\\MySQL\\Driver.php:33)\n[previous exception] [object] (PDOException(code: 0): PDO::__construct(): php_network_getaddresses: getaddrinfo for mysql failed: Hï¿½te inconnu.  at C:\\Users\\CDAX27\\covoiturage\\vendor\\doctrine\\dbal\\src\\Driver\\PDO\\MySQL\\Driver.php:33)"} []
[2025-03-03T15:18:57.137341+01:00] request.INFO: Matched route "api_login". {"route":"api_login","route_parameters":{"_route":"api_login","_controller":"App\\Controller\\SecurityController::login"},"request_uri":"http://localhost/api/login_check","method":"POST"} []
[2025-03-03T15:18:57.206159+01:00] security.DEBUG: Checking for authenticator support. {"firewall_name":"login","authenticators":1} []
[2025-03-03T15:18:57.206168+01:00] security.DEBUG: Checking support on authenticator. {"firewall_name":"login","authenticator":"Symfony\\Component\\Security\\Http\\Authenticator\\Debug\\TraceableAuthenticator"} []
[2025-03-03T15:18:57.420020+01:00] doctrine.INFO: Connecting with parameters array{"use_savepoints":true,"dbname_suffix":"_test","driver":"pdo_mysql","idle_connection_ttl":600,"host":"mysql","port":3306,"user":"user","password":"<redacted>","driverOptions":[],"defaultTableOptions":[],"dbname":"db_test","charset":"utf8mb4","serverVersion":"10.6.21-MariaDB"} {"params":{"use_savepoints":true,"dbname_suffix":"_test","driver":"pdo_mysql","idle_connection_ttl":600,"host":"mysql","port":3306,"user":"user","password":"<redacted>","driverOptions":[],"defaultTableOptions":[],"dbname":"db_test","charset":"utf8mb4","serverVersion":"10.6.21-MariaDB"}} []
[2025-03-03T15:19:00.198749+01:00] request.CRITICAL: Uncaught PHP Exception Doctrine\DBAL\Exception\ConnectionException: "An exception occurred in the driver: SQLSTATE[HY000] [2002] php_network_getaddresses: getaddrinfo for mysql failed: Hôte inconnu. " at ExceptionConverter.php line 101 {"exception":"[object] (Doctrine\\DBAL\\Exception\\ConnectionException(code: 2002): An exception occurred in the driver: SQLSTATE[HY000] [2002] php_network_getaddresses: getaddrinfo for mysql failed: Hï¿½te inconnu.  at C:\\Users\\CDAX27\\covoiturage\\vendor\\doctrine\\dbal\\src\\Driver\\API\\MySQL\\ExceptionConverter.php:101)\n[previous exception] [object] (Doctrine\\DBAL\\Driver\\PDO\\Exception(code: 2002): SQLSTATE[HY000] [2002] php_network_getaddresses: getaddrinfo for mysql failed: Hï¿½te inconnu.  at C:\\Users\\CDAX27\\covoiturage\\vendor\\doctrine\\dbal\\src\\Driver\\PDO\\Exception.php:24)\n[previous exception] [object] (PDOException(code: 2002): SQLSTATE[HY000] [2002] php_network_getaddresses: getaddrinfo for mysql failed: Hï¿½te inconnu.  at C:\\Users\\CDAX27\\covoiturage\\vendor\\doctrine\\dbal\\src\\Driver\\PDO\\MySQL\\Driver.php:33)\n[previous exception] [object] (PDOException(code: 0): PDO::__construct(): php_network_getaddresses: getaddrinfo for mysql failed: Hï¿½te inconnu.  at C:\\Users\\CDAX27\\covoiturage\\vendor\\doctrine\\dbal\\src\\Driver\\PDO\\MySQL\\Driver.php:33)"} []
[2025-03-04T16:05:02.946640+01:00] request.INFO: Matched route "api_login". {"route":"api_login","route_parameters":{"_route":"api_login","_controller":"App\\Controller\\SecurityController::login"},"request_uri":"http://localhost/api/login_check","method":"POST"} []
[2025-03-04T16:05:03.010689+01:00] security.DEBUG: Checking for authenticator support. {"firewall_name":"login","authenticators":1} []
[2025-03-04T16:05:03.010701+01:00] security.DEBUG: Checking support on authenticator. {"firewall_name":"login","authenticator":"Symfony\\Component\\Security\\Http\\Authenticator\\Debug\\TraceableAuthenticator"} []
[2025-03-04T16:05:03.010721+01:00] security.DEBUG: Authenticator does not support the request. {"firewall_name":"login","authenticator":"Symfony\\Component\\Security\\Http\\Authenticator\\Debug\\TraceableAuthenticator"} []
[2025-03-04T16:05:03.032308+01:00] security.DEBUG: Access denied, the user is not fully authenticated; redirecting to authentication entry point. {"exception":"[object] (Symfony\\Component\\Security\\Core\\Exception\\AccessDeniedException(code: 403): Access Denied. at C:\\Users\\CDAX27\\covoiturage\\vendor\\symfony\\security-http\\Firewall\\AccessListener.php:83)"} []
[2025-03-04T16:05:03.033782+01:00] security.NOTICE: No Authentication entry point configured, returning a 401 HTTP response. Configure "entry_point" on the firewall "login" if you want to modify the response. [] []
[2025-03-04T16:05:03.038253+01:00] request.ERROR: Uncaught PHP Exception Symfony\Component\HttpKernel\Exception\HttpException: "Full authentication is required to access this resource." at ExceptionListener.php line 216 {"exception":"[object] (Symfony\\Component\\HttpKernel\\Exception\\HttpException(code: 0): Full authentication is required to access this resource. at C:\\Users\\CDAX27\\covoiturage\\vendor\\symfony\\security-http\\Firewall\\ExceptionListener.php:216)\n[previous exception] [object] (Symfony\\Component\\Security\\Core\\Exception\\InsufficientAuthenticationException(code: 0): Full authentication is required to access this resource. at C:\\Users\\CDAX27\\covoiturage\\vendor\\symfony\\security-http\\Firewall\\ExceptionListener.php:133)\n[previous exception] [object] (Symfony\\Component\\Security\\Core\\Exception\\AccessDeniedException(code: 403): Access Denied. at C:\\Users\\CDAX27\\covoiturage\\vendor\\symfony\\security-http\\Firewall\\AccessListener.php:83)"} []
[2025-03-06T09:55:15.294911+01:00] console.CRITICAL: Error thrown while running command ""doctrine:database:info" --env=test". Message: "Command "doctrine:database:info" is not defined.  Did you mean one of these?     doctrine:database:create     doctrine:database:drop     doctrine:mapping:info" {"exception":"[object] (Symfony\\Component\\Console\\Exception\\CommandNotFoundException(code: 0): Command \"doctrine:database:info\" is not defined.\n\nDid you mean one of these?\n    doctrine:database:create\n    doctrine:database:drop\n    doctrine:mapping:info at C:\\Users\\CDAX27\\covoiturage\\vendor\\symfony\\console\\Application.php:726)","command":"\"doctrine:database:info\" --env=test","message":"Command \"doctrine:database:info\" is not defined.\n\nDid you mean one of these?\n    doctrine:database:create\n    doctrine:database:drop\n    doctrine:mapping:info"} []
[2025-03-06T10:47:57.698451+01:00] doctrine.INFO: Connecting with parameters array{"host":"greta-bretagne-sud.org","port":3306,"driver":"pdo_mysql","use_savepoints":true,"dbname_suffix":"_test","idle_connection_ttl":600,"user":"tima6358_amina","password":"<redacted>","driverOptions":[],"defaultTableOptions":[],"serverVersion":"10.6.21-MariaDB","charset":"utf8mb4"} {"params":{"host":"greta-bretagne-sud.org","port":3306,"driver":"pdo_mysql","use_savepoints":true,"dbname_suffix":"_test","idle_connection_ttl":600,"user":"tima6358_amina","password":"<redacted>","driverOptions":[],"defaultTableOptions":[],"serverVersion":"10.6.21-MariaDB","charset":"utf8mb4"}} []
[2025-03-06T10:48:18.770513+01:00] console.CRITICAL: Error thrown while running command "doctrine:database:create --if-not-exists --env=test". Message: "An exception occurred in the driver: SQLSTATE[HY000] [2002] Une tentative de connexion a Ã©chouÃ© car le parti connectÃ© nâa pas rÃ©pondu convenablement au-delÃ  dâune certaine durÃ©e ou une connexion Ã©tablie a Ã©chouÃ© car lâhÃ´te de connexion nâa pas rÃ©pondu" {"exception":"[object] (Doctrine\\DBAL\\Exception\\ConnectionException(code: 2002): An exception occurred in the driver: SQLSTATE[HY000] [2002] Une tentative de connexion a Ã©chouÃ© car le parti connectÃ© nâa pas rÃ©pondu convenablement au-delÃ  dâune certaine durÃ©e ou une connexion Ã©tablie a Ã©chouÃ© car lâhÃ´te de connexion nâa pas rÃ©pondu at C:\\Users\\CDAX27\\covoiturage\\vendor\\doctrine\\dbal\\src\\Driver\\API\\MySQL\\ExceptionConverter.php:101)\n[previous exception] [object] (Doctrine\\DBAL\\Driver\\PDO\\Exception(code: 2002): SQLSTATE[HY000] [2002] Une tentative de connexion a Ã©chouÃ© car le parti connectÃ© nâa pas rÃ©pondu convenablement au-delÃ  dâune certaine durÃ©e ou une connexion Ã©tablie a Ã©chouÃ© car lâhÃ´te de connexion nâa pas rÃ©pondu at C:\\Users\\CDAX27\\covoiturage\\vendor\\doctrine\\dbal\\src\\Driver\\PDO\\Exception.php:24)\n[previous exception] [object] (PDOException(code: 2002): SQLSTATE[HY000] [2002] Une tentative de connexion a Ã©chouÃ© car le parti connectÃ© nâa pas rÃ©pondu convenablement au-delÃ  dâune certaine durÃ©e ou une connexion Ã©tablie a Ã©chouÃ© car lâhÃ´te de connexion nâa pas rÃ©pondu at C:\\Users\\CDAX27\\covoiturage\\vendor\\doctrine\\dbal\\src\\Driver\\PDO\\MySQL\\Driver.php:33)","command":"doctrine:database:create --if-not-exists --env=test","message":"An exception occurred in the driver: SQLSTATE[HY000] [2002] Une tentative de connexion a Ã©chouÃ© car le parti connectÃ© nâa pas rÃ©pondu convenablement au-delÃ  dâune certaine durÃ©e ou une connexion Ã©tablie a Ã©chouÃ© car lâhÃ´te de connexion nâa pas rÃ©pondu"} []
[2025-03-06T10:48:18.778899+01:00] console.DEBUG: Command "doctrine:database:create --if-not-exists --env=test" exited with code "2002" {"command":"doctrine:database:create --if-not-exists --env=test","code":2002} []
[2025-03-06T10:59:20.900002+01:00] doctrine.INFO: Connecting with parameters array{"host":"localhost","port":3306,"driver":"pdo_mysql","use_savepoints":true,"dbname_suffix":"_test","idle_connection_ttl":600,"user":"tima6358_amina","password":"<redacted>","driverOptions":[],"defaultTableOptions":[],"serverVersion":"10.6.21-MariaDB","charset":"utf8mb4"} {"params":{"host":"localhost","port":3306,"driver":"pdo_mysql","use_savepoints":true,"dbname_suffix":"_test","idle_connection_ttl":600,"user":"tima6358_amina","password":"<redacted>","driverOptions":[],"defaultTableOptions":[],"serverVersion":"10.6.21-MariaDB","charset":"utf8mb4"}} []
[2025-03-06T10:59:20.939469+01:00] console.CRITICAL: Error thrown while running command "doctrine:database:create --if-not-exists --env=test". Message: "An exception occurred in the driver: SQLSTATE[HY000] [1524] Plugin 'mysql_native_password' is not loaded" {"exception":"[object] (Doctrine\\DBAL\\Exception\\DriverException(code: 1524): An exception occurred in the driver: SQLSTATE[HY000] [1524] Plugin 'mysql_native_password' is not loaded at C:\\Users\\CDAX27\\covoiturage\\vendor\\doctrine\\dbal\\src\\Driver\\API\\MySQL\\ExceptionConverter.php:118)\n[previous exception] [object] (Doctrine\\DBAL\\Driver\\PDO\\Exception(code: 1524): SQLSTATE[HY000] [1524] Plugin 'mysql_native_password' is not loaded at C:\\Users\\CDAX27\\covoiturage\\vendor\\doctrine\\dbal\\src\\Driver\\PDO\\Exception.php:24)\n[previous exception] [object] (PDOException(code: 1524): SQLSTATE[HY000] [1524] Plugin 'mysql_native_password' is not loaded at C:\\Users\\CDAX27\\covoiturage\\vendor\\doctrine\\dbal\\src\\Driver\\PDO\\MySQL\\Driver.php:33)","command":"doctrine:database:create --if-not-exists --env=test","message":"An exception occurred in the driver: SQLSTATE[HY000] [1524] Plugin 'mysql_native_password' is not loaded"} []
[2025-03-06T10:59:20.946755+01:00] console.DEBUG: Command "doctrine:database:create --if-not-exists --env=test" exited with code "1524" {"command":"doctrine:database:create --if-not-exists --env=test","code":1524} []
[2025-03-06T11:03:47.320751+01:00] doctrine.INFO: Connecting with parameters array{"host":"localhost","port":3306,"driver":"pdo_mysql","use_savepoints":true,"dbname_suffix":"_test","idle_connection_ttl":600,"user":"tima6358_amina","password":"<redacted>","driverOptions":[],"defaultTableOptions":[],"serverVersion":"10.6.21-MariaDB","charset":"utf8mb4","default-auth":"mysql_native_password"} {"params":{"host":"localhost","port":3306,"driver":"pdo_mysql","use_savepoints":true,"dbname_suffix":"_test","idle_connection_ttl":600,"user":"tima6358_amina","password":"<redacted>","driverOptions":[],"defaultTableOptions":[],"serverVersion":"10.6.21-MariaDB","charset":"utf8mb4","default-auth":"mysql_native_password"}} []
[2025-03-06T11:03:47.347931+01:00] console.CRITICAL: Error thrown while running command "doctrine:database:create --if-not-exists --env=test". Message: "An exception occurred in the driver: SQLSTATE[HY000] [1524] Plugin 'mysql_native_password' is not loaded" {"exception":"[object] (Doctrine\\DBAL\\Exception\\DriverException(code: 1524): An exception occurred in the driver: SQLSTATE[HY000] [1524] Plugin 'mysql_native_password' is not loaded at C:\\Users\\CDAX27\\covoiturage\\vendor\\doctrine\\dbal\\src\\Driver\\API\\MySQL\\ExceptionConverter.php:118)\n[previous exception] [object] (Doctrine\\DBAL\\Driver\\PDO\\Exception(code: 1524): SQLSTATE[HY000] [1524] Plugin 'mysql_native_password' is not loaded at C:\\Users\\CDAX27\\covoiturage\\vendor\\doctrine\\dbal\\src\\Driver\\PDO\\Exception.php:24)\n[previous exception] [object] (PDOException(code: 1524): SQLSTATE[HY000] [1524] Plugin 'mysql_native_password' is not loaded at C:\\Users\\CDAX27\\covoiturage\\vendor\\doctrine\\dbal\\src\\Driver\\PDO\\MySQL\\Driver.php:33)","command":"doctrine:database:create --if-not-exists --env=test","message":"An exception occurred in the driver: SQLSTATE[HY000] [1524] Plugin 'mysql_native_password' is not loaded"} []
[2025-03-06T11:03:47.354234+01:00] console.DEBUG: Command "doctrine:database:create --if-not-exists --env=test" exited with code "1524" {"command":"doctrine:database:create --if-not-exists --env=test","code":1524} []
[2025-03-06T11:18:23.688587+01:00] doctrine.INFO: Connecting with parameters array{"host":"localhost","port":3306,"driver":"pdo_sqlite","use_savepoints":true,"dbname_suffix":"_test","idle_connection_ttl":600,"user":"root","password":null,"driverOptions":[],"defaultTableOptions":[],"path":"%kernel.project_dir%/var/test.db","charset":"utf8"} {"params":{"host":"localhost","port":3306,"driver":"pdo_sqlite","use_savepoints":true,"dbname_suffix":"_test","idle_connection_ttl":600,"user":"root","password":null,"driverOptions":[],"defaultTableOptions":[],"path":"%kernel.project_dir%/var/test.db","charset":"utf8"}} []
[2025-03-06T11:18:23.707898+01:00] console.CRITICAL: Error thrown while running command "doctrine:database:create --if-not-exists --env=test". Message: "An exception occurred in the driver: SQLSTATE[HY000] [14] unable to open database file" {"exception":"[object] (Doctrine\\DBAL\\Exception\\ConnectionException(code: 14): An exception occurred in the driver: SQLSTATE[HY000] [14] unable to open database file at C:\\Users\\CDAX27\\covoiturage\\vendor\\doctrine\\dbal\\src\\Driver\\API\\SQLite\\ExceptionConverter.php:76)\n[previous exception] [object] (Doctrine\\DBAL\\Driver\\PDO\\Exception(code: 14): SQLSTATE[HY000] [14] unable to open database file at C:\\Users\\CDAX27\\covoiturage\\vendor\\doctrine\\dbal\\src\\Driver\\PDO\\Exception.php:24)\n[previous exception] [object] (PDOException(code: 14): SQLSTATE[HY000] [14] unable to open database file at C:\\Users\\CDAX27\\covoiturage\\vendor\\doctrine\\dbal\\src\\Driver\\PDO\\SQLite\\Driver.php:43)","command":"doctrine:database:create --if-not-exists --env=test","message":"An exception occurred in the driver: SQLSTATE[HY000] [14] unable to open database file"} []
[2025-03-06T11:18:23.715608+01:00] console.DEBUG: Command "doctrine:database:create --if-not-exists --env=test" exited with code "14" {"command":"doctrine:database:create --if-not-exists --env=test","code":14} []
[2025-03-06T11:53:30.962562+01:00] doctrine.INFO: Connecting with parameters array{"host":"localhost","port":3306,"driver":"pdo_sqlite","use_savepoints":true,"dbname_suffix":"_test","idle_connection_ttl":600,"user":"root","password":null,"driverOptions":[],"defaultTableOptions":[],"path":"%kernel.project_dir%/var/test.db","charset":"utf8"} {"params":{"host":"localhost","port":3306,"driver":"pdo_sqlite","use_savepoints":true,"dbname_suffix":"_test","idle_connection_ttl":600,"user":"root","password":null,"driverOptions":[],"defaultTableOptions":[],"path":"%kernel.project_dir%/var/test.db","charset":"utf8"}} []
[2025-03-06T11:53:30.977906+01:00] console.CRITICAL: Error thrown while running command "doctrine:database:create --env=test". Message: "An exception occurred in the driver: SQLSTATE[HY000] [14] unable to open database file" {"exception":"[object] (Doctrine\\DBAL\\Exception\\ConnectionException(code: 14): An exception occurred in the driver: SQLSTATE[HY000] [14] unable to open database file at C:\\Users\\CDAX27\\covoiturage\\vendor\\doctrine\\dbal\\src\\Driver\\API\\SQLite\\ExceptionConverter.php:76)\n[previous exception] [object] (Doctrine\\DBAL\\Driver\\PDO\\Exception(code: 14): SQLSTATE[HY000] [14] unable to open database file at C:\\Users\\CDAX27\\covoiturage\\vendor\\doctrine\\dbal\\src\\Driver\\PDO\\Exception.php:24)\n[previous exception] [object] (PDOException(code: 14): SQLSTATE[HY000] [14] unable to open database file at C:\\Users\\CDAX27\\covoiturage\\vendor\\doctrine\\dbal\\src\\Driver\\PDO\\SQLite\\Driver.php:43)","command":"doctrine:database:create --env=test","message":"An exception occurred in the driver: SQLSTATE[HY000] [14] unable to open database file"} []
[2025-03-06T11:53:30.984568+01:00] console.DEBUG: Command "doctrine:database:create --env=test" exited with code "14" {"command":"doctrine:database:create --env=test","code":14} []
[2025-03-06T11:53:40.795983+01:00] doctrine.INFO: Connecting with parameters array{"host":"localhost","port":3306,"driver":"pdo_sqlite","use_savepoints":true,"dbname_suffix":"_test","idle_connection_ttl":600,"user":"root","password":null,"driverOptions":[],"defaultTableOptions":[],"path":"%kernel.project_dir%/var/test.db","charset":"utf8"} {"params":{"host":"localhost","port":3306,"driver":"pdo_sqlite","use_savepoints":true,"dbname_suffix":"_test","idle_connection_ttl":600,"user":"root","password":null,"driverOptions":[],"defaultTableOptions":[],"path":"%kernel.project_dir%/var/test.db","charset":"utf8"}} []
[2025-03-06T11:53:40.815132+01:00] console.CRITICAL: Error thrown while running command "doctrine:database:create --env=test". Message: "An exception occurred in the driver: SQLSTATE[HY000] [14] unable to open database file" {"exception":"[object] (Doctrine\\DBAL\\Exception\\ConnectionException(code: 14): An exception occurred in the driver: SQLSTATE[HY000] [14] unable to open database file at C:\\Users\\CDAX27\\covoiturage\\vendor\\doctrine\\dbal\\src\\Driver\\API\\SQLite\\ExceptionConverter.php:76)\n[previous exception] [object] (Doctrine\\DBAL\\Driver\\PDO\\Exception(code: 14): SQLSTATE[HY000] [14] unable to open database file at C:\\Users\\CDAX27\\covoiturage\\vendor\\doctrine\\dbal\\src\\Driver\\PDO\\Exception.php:24)\n[previous exception] [object] (PDOException(code: 14): SQLSTATE[HY000] [14] unable to open database file at C:\\Users\\CDAX27\\covoiturage\\vendor\\doctrine\\dbal\\src\\Driver\\PDO\\SQLite\\Driver.php:43)","command":"doctrine:database:create --env=test","message":"An exception occurred in the driver: SQLSTATE[HY000] [14] unable to open database file"} []
[2025-03-06T11:53:40.821937+01:00] console.DEBUG: Command "doctrine:database:create --env=test" exited with code "14" {"command":"doctrine:database:create --env=test","code":14} []
[2025-03-06T12:15:02.326509+01:00] console.CRITICAL: Error thrown while running command ""doctrine:database:exists" --env=test". Message: "Command "doctrine:database:exists" is not defined.  Did you mean one of these?     doctrine:database:create     doctrine:database:drop" {"exception":"[object] (Symfony\\Component\\Console\\Exception\\CommandNotFoundException(code: 0): Command \"doctrine:database:exists\" is not defined.\n\nDid you mean one of these?\n    doctrine:database:create\n    doctrine:database:drop at C:\\Users\\CDAX27\\covoiturage\\vendor\\symfony\\console\\Application.php:726)","command":"\"doctrine:database:exists\" --env=test","message":"Command \"doctrine:database:exists\" is not defined.\n\nDid you mean one of these?\n    doctrine:database:create\n    doctrine:database:drop"} []
[2025-03-06T12:15:45.691757+01:00] deprecation.INFO: User Deprecated: Since doctrine/doctrine-bundle 2.2: The "Doctrine\Bundle\DoctrineBundle\Command\Proxy\RunSqlDoctrineCommand" (doctrine:query:sql) is deprecated, use dbal:run-sql command instead. {"exception":"[object] (ErrorException(code: 0): User Deprecated: Since doctrine/doctrine-bundle 2.2: The \"Doctrine\\Bundle\\DoctrineBundle\\Command\\Proxy\\RunSqlDoctrineCommand\" (doctrine:query:sql) is deprecated, use dbal:run-sql command instead. at C:\\Users\\CDAX27\\covoiturage\\vendor\\doctrine\\doctrine-bundle\\src\\Command\\Proxy\\RunSqlDoctrineCommand.php:34)"} []
[2025-03-06T12:15:45.714775+01:00] doctrine.INFO: Connecting with parameters array{"host":"localhost","port":3306,"driver":"pdo_sqlite","use_savepoints":true,"dbname_suffix":"_test","idle_connection_ttl":600,"user":"root","password":null,"driverOptions":[],"defaultTableOptions":[],"path":"%kernel.project_dir%/var/test.db","charset":"utf8"} {"params":{"host":"localhost","port":3306,"driver":"pdo_sqlite","use_savepoints":true,"dbname_suffix":"_test","idle_connection_ttl":600,"user":"root","password":null,"driverOptions":[],"defaultTableOptions":[],"path":"%kernel.project_dir%/var/test.db","charset":"utf8"}} []
[2025-03-06T12:15:45.730349+01:00] console.CRITICAL: Error thrown while running command "doctrine:query:sql "SELECT sqlite_version();" --env=test". Message: "An exception occurred in the driver: SQLSTATE[HY000] [14] unable to open database file" {"exception":"[object] (Doctrine\\DBAL\\Exception\\ConnectionException(code: 14): An exception occurred in the driver: SQLSTATE[HY000] [14] unable to open database file at C:\\Users\\CDAX27\\covoiturage\\vendor\\doctrine\\dbal\\src\\Driver\\API\\SQLite\\ExceptionConverter.php:76)\n[previous exception] [object] (Doctrine\\DBAL\\Driver\\PDO\\Exception(code: 14): SQLSTATE[HY000] [14] unable to open database file at C:\\Users\\CDAX27\\covoiturage\\vendor\\doctrine\\dbal\\src\\Driver\\PDO\\Exception.php:24)\n[previous exception] [object] (PDOException(code: 14): SQLSTATE[HY000] [14] unable to open database file at C:\\Users\\CDAX27\\covoiturage\\vendor\\doctrine\\dbal\\src\\Driver\\PDO\\SQLite\\Driver.php:43)","command":"doctrine:query:sql \"SELECT sqlite_version();\" --env=test","message":"An exception occurred in the driver: SQLSTATE[HY000] [14] unable to open database file"} []
[2025-03-06T12:15:45.736442+01:00] console.DEBUG: Command "doctrine:query:sql "SELECT sqlite_version();" --env=test" exited with code "14" {"command":"doctrine:query:sql \"SELECT sqlite_version();\" --env=test","code":14} []
[2025-03-06T12:16:01.989969+01:00] doctrine.INFO: Connecting with parameters array{"host":"localhost","port":3306,"driver":"pdo_sqlite","use_savepoints":true,"dbname_suffix":"_test","idle_connection_ttl":600,"user":"root","password":null,"driverOptions":[],"defaultTableOptions":[],"path":"%kernel.project_dir%/var/test.db","charset":"utf8"} {"params":{"host":"localhost","port":3306,"driver":"pdo_sqlite","use_savepoints":true,"dbname_suffix":"_test","idle_connection_ttl":600,"user":"root","password":null,"driverOptions":[],"defaultTableOptions":[],"path":"%kernel.project_dir%/var/test.db","charset":"utf8"}} []
[2025-03-06T12:16:02.018305+01:00] console.CRITICAL: Error thrown while running command "doctrine:schema:update --force --env=test". Message: "An exception occurred in the driver: SQLSTATE[HY000] [14] unable to open database file" {"exception":"[object] (Doctrine\\DBAL\\Exception\\ConnectionException(code: 14): An exception occurred in the driver: SQLSTATE[HY000] [14] unable to open database file at C:\\Users\\CDAX27\\covoiturage\\vendor\\doctrine\\dbal\\src\\Driver\\API\\SQLite\\ExceptionConverter.php:76)\n[previous exception] [object] (Doctrine\\DBAL\\Driver\\PDO\\Exception(code: 14): SQLSTATE[HY000] [14] unable to open database file at C:\\Users\\CDAX27\\covoiturage\\vendor\\doctrine\\dbal\\src\\Driver\\PDO\\Exception.php:24)\n[previous exception] [object] (PDOException(code: 14): SQLSTATE[HY000] [14] unable to open database file at C:\\Users\\CDAX27\\covoiturage\\vendor\\doctrine\\dbal\\src\\Driver\\PDO\\SQLite\\Driver.php:43)","command":"doctrine:schema:update --force --env=test","message":"An exception occurred in the driver: SQLSTATE[HY000] [14] unable to open database file"} []
[2025-03-06T12:16:02.028814+01:00] console.DEBUG: Command "doctrine:schema:update --force --env=test" exited with code "14" {"command":"doctrine:schema:update --force --env=test","code":14} []
[2025-03-06T12:16:08.659218+01:00] doctrine.INFO: Connecting with parameters array{"host":"localhost","port":3306,"driver":"pdo_sqlite","use_savepoints":true,"dbname_suffix":"_test","idle_connection_ttl":600,"user":"root","password":null,"driverOptions":[],"defaultTableOptions":[],"path":"%kernel.project_dir%/var/test.db","charset":"utf8"} {"params":{"host":"localhost","port":3306,"driver":"pdo_sqlite","use_savepoints":true,"dbname_suffix":"_test","idle_connection_ttl":600,"user":"root","password":null,"driverOptions":[],"defaultTableOptions":[],"path":"%kernel.project_dir%/var/test.db","charset":"utf8"}} []
[2025-03-06T12:16:08.678868+01:00] console.CRITICAL: Error thrown while running command "doctrine:schema:validate --env=test". Message: "An exception occurred in the driver: SQLSTATE[HY000] [14] unable to open database file" {"exception":"[object] (Doctrine\\DBAL\\Exception\\ConnectionException(code: 14): An exception occurred in the driver: SQLSTATE[HY000] [14] unable to open database file at C:\\Users\\CDAX27\\covoiturage\\vendor\\doctrine\\dbal\\src\\Driver\\API\\SQLite\\ExceptionConverter.php:76)\n[previous exception] [object] (Doctrine\\DBAL\\Driver\\PDO\\Exception(code: 14): SQLSTATE[HY000] [14] unable to open database file at C:\\Users\\CDAX27\\covoiturage\\vendor\\doctrine\\dbal\\src\\Driver\\PDO\\Exception.php:24)\n[previous exception] [object] (PDOException(code: 14): SQLSTATE[HY000] [14] unable to open database file at C:\\Users\\CDAX27\\covoiturage\\vendor\\doctrine\\dbal\\src\\Driver\\PDO\\SQLite\\Driver.php:43)","command":"doctrine:schema:validate --env=test","message":"An exception occurred in the driver: SQLSTATE[HY000] [14] unable to open database file"} []
[2025-03-06T12:16:08.689180+01:00] console.DEBUG: Command "doctrine:schema:validate --env=test" exited with code "14" {"command":"doctrine:schema:validate --env=test","code":14} []
[2025-03-06T12:16:55.498232+01:00] doctrine.INFO: Connecting with parameters array{"host":"localhost","port":3306,"driver":"pdo_sqlite","use_savepoints":true,"dbname_suffix":"_test","idle_connection_ttl":600,"user":"root","password":null,"driverOptions":[],"defaultTableOptions":[],"path":"%kernel.project_dir%/var/test.db","charset":"utf8"} {"params":{"host":"localhost","port":3306,"driver":"pdo_sqlite","use_savepoints":true,"dbname_suffix":"_test","idle_connection_ttl":600,"user":"root","password":null,"driverOptions":[],"defaultTableOptions":[],"path":"%kernel.project_dir%/var/test.db","charset":"utf8"}} []
[2025-03-06T12:16:55.523389+01:00] console.CRITICAL: Error thrown while running command "doctrine:database:create --env=test". Message: "An exception occurred in the driver: SQLSTATE[HY000] [14] unable to open database file" {"exception":"[object] (Doctrine\\DBAL\\Exception\\ConnectionException(code: 14): An exception occurred in the driver: SQLSTATE[HY000] [14] unable to open database file at C:\\Users\\CDAX27\\covoiturage\\vendor\\doctrine\\dbal\\src\\Driver\\API\\SQLite\\ExceptionConverter.php:76)\n[previous exception] [object] (Doctrine\\DBAL\\Driver\\PDO\\Exception(code: 14): SQLSTATE[HY000] [14] unable to open database file at C:\\Users\\CDAX27\\covoiturage\\vendor\\doctrine\\dbal\\src\\Driver\\PDO\\Exception.php:24)\n[previous exception] [object] (PDOException(code: 14): SQLSTATE[HY000] [14] unable to open database file at C:\\Users\\CDAX27\\covoiturage\\vendor\\doctrine\\dbal\\src\\Driver\\PDO\\SQLite\\Driver.php:43)","command":"doctrine:database:create --env=test","message":"An exception occurred in the driver: SQLSTATE[HY000] [14] unable to open database file"} []
[2025-03-06T12:16:55.531419+01:00] console.DEBUG: Command "doctrine:database:create --env=test" exited with code "14" {"command":"doctrine:database:create --env=test","code":14} []
[2025-03-06T12:17:05.568423+01:00] doctrine.INFO: Connecting with parameters array{"host":"localhost","port":3306,"driver":"pdo_sqlite","use_savepoints":true,"dbname_suffix":"_test","idle_connection_ttl":600,"user":"root","password":null,"driverOptions":[],"defaultTableOptions":[],"path":"%kernel.project_dir%/var/test.db","charset":"utf8"} {"params":{"host":"localhost","port":3306,"driver":"pdo_sqlite","use_savepoints":true,"dbname_suffix":"_test","idle_connection_ttl":600,"user":"root","password":null,"driverOptions":[],"defaultTableOptions":[],"path":"%kernel.project_dir%/var/test.db","charset":"utf8"}} []
[2025-03-06T12:17:05.590547+01:00] console.CRITICAL: Error thrown while running command "doctrine:schema:update --force --env=test". Message: "An exception occurred in the driver: SQLSTATE[HY000] [14] unable to open database file" {"exception":"[object] (Doctrine\\DBAL\\Exception\\ConnectionException(code: 14): An exception occurred in the driver: SQLSTATE[HY000] [14] unable to open database file at C:\\Users\\CDAX27\\covoiturage\\vendor\\doctrine\\dbal\\src\\Driver\\API\\SQLite\\ExceptionConverter.php:76)\n[previous exception] [object] (Doctrine\\DBAL\\Driver\\PDO\\Exception(code: 14): SQLSTATE[HY000] [14] unable to open database file at C:\\Users\\CDAX27\\covoiturage\\vendor\\doctrine\\dbal\\src\\Driver\\PDO\\Exception.php:24)\n[previous exception] [object] (PDOException(code: 14): SQLSTATE[HY000] [14] unable to open database file at C:\\Users\\CDAX27\\covoiturage\\vendor\\doctrine\\dbal\\src\\Driver\\PDO\\SQLite\\Driver.php:43)","command":"doctrine:schema:update --force --env=test","message":"An exception occurred in the driver: SQLSTATE[HY000] [14] unable to open database file"} []
[2025-03-06T12:17:05.597687+01:00] console.DEBUG: Command "doctrine:schema:update --force --env=test" exited with code "14" {"command":"doctrine:schema:update --force --env=test","code":14} []
[2025-03-06T12:27:43.820551+01:00] doctrine.INFO: Connecting with parameters array{"host":"localhost","port":3306,"driver":"pdo_sqlite","use_savepoints":true,"dbname_suffix":"_test","idle_connection_ttl":600,"user":"root","password":null,"driverOptions":[],"defaultTableOptions":[],"path":"%kernel.project_dir%/var/test.db","charset":"utf8"} {"params":{"host":"localhost","port":3306,"driver":"pdo_sqlite","use_savepoints":true,"dbname_suffix":"_test","idle_connection_ttl":600,"user":"root","password":null,"driverOptions":[],"defaultTableOptions":[],"path":"%kernel.project_dir%/var/test.db","charset":"utf8"}} []
[2025-03-06T12:27:43.839350+01:00] console.CRITICAL: Error thrown while running command "doctrine:database:create --env=test". Message: "An exception occurred in the driver: SQLSTATE[HY000] [14] unable to open database file" {"exception":"[object] (Doctrine\\DBAL\\Exception\\ConnectionException(code: 14): An exception occurred in the driver: SQLSTATE[HY000] [14] unable to open database file at C:\\Users\\CDAX27\\covoiturage\\vendor\\doctrine\\dbal\\src\\Driver\\API\\SQLite\\ExceptionConverter.php:76)\n[previous exception] [object] (Doctrine\\DBAL\\Driver\\PDO\\Exception(code: 14): SQLSTATE[HY000] [14] unable to open database file at C:\\Users\\CDAX27\\covoiturage\\vendor\\doctrine\\dbal\\src\\Driver\\PDO\\Exception.php:24)\n[previous exception] [object] (PDOException(code: 14): SQLSTATE[HY000] [14] unable to open database file at C:\\Users\\CDAX27\\covoiturage\\vendor\\doctrine\\dbal\\src\\Driver\\PDO\\SQLite\\Driver.php:43)","command":"doctrine:database:create --env=test","message":"An exception occurred in the driver: SQLSTATE[HY000] [14] unable to open database file"} []
[2025-03-06T12:27:43.848599+01:00] console.DEBUG: Command "doctrine:database:create --env=test" exited with code "14" {"command":"doctrine:database:create --env=test","code":14} []
[2025-03-06T13:02:45.189372+01:00] doctrine.INFO: Connecting with parameters array{"host":"127.0.0.1","port":3306,"driver":"pdo_mysql","use_savepoints":true,"dbname_suffix":"_test","idle_connection_ttl":600,"user":"amina","password":"<redacted>","driverOptions":[],"defaultTableOptions":[],"dbname":"covoiturage_test","serverVersion":"8.0.41","charset":"utf8mb4"} {"params":{"host":"127.0.0.1","port":3306,"driver":"pdo_mysql","use_savepoints":true,"dbname_suffix":"_test","idle_connection_ttl":600,"user":"amina","password":"<redacted>","driverOptions":[],"defaultTableOptions":[],"dbname":"covoiturage_test","serverVersion":"8.0.41","charset":"utf8mb4"}} []
[2025-03-06T13:02:45.206558+01:00] console.CRITICAL: Error thrown while running command "doctrine:schema:drop --force --env=test". Message: "An exception occurred in the driver: SQLSTATE[HY000] [1524] Plugin 'mysql_native_password' is not loaded" {"exception":"[object] (Doctrine\\DBAL\\Exception\\DriverException(code: 1524): An exception occurred in the driver: SQLSTATE[HY000] [1524] Plugin 'mysql_native_password' is not loaded at C:\\Users\\CDAX27\\covoiturage\\vendor\\doctrine\\dbal\\src\\Driver\\API\\MySQL\\ExceptionConverter.php:118)\n[previous exception] [object] (Doctrine\\DBAL\\Driver\\PDO\\Exception(code: 1524): SQLSTATE[HY000] [1524] Plugin 'mysql_native_password' is not loaded at C:\\Users\\CDAX27\\covoiturage\\vendor\\doctrine\\dbal\\src\\Driver\\PDO\\Exception.php:24)\n[previous exception] [object] (PDOException(code: 1524): SQLSTATE[HY000] [1524] Plugin 'mysql_native_password' is not loaded at C:\\Users\\CDAX27\\covoiturage\\vendor\\doctrine\\dbal\\src\\Driver\\PDO\\MySQL\\Driver.php:33)","command":"doctrine:schema:drop --force --env=test","message":"An exception occurred in the driver: SQLSTATE[HY000] [1524] Plugin 'mysql_native_password' is not loaded"} []
[2025-03-06T13:02:45.216378+01:00] console.DEBUG: Command "doctrine:schema:drop --force --env=test" exited with code "1524" {"command":"doctrine:schema:drop --force --env=test","code":1524} []
[2025-03-06T13:43:13.455554+00:00] request.INFO: Matched route "api_login". {"route":"api_login","route_parameters":{"_route":"api_login","_controller":"App\\Controller\\SecurityController::login"},"request_uri":"http://localhost/api/login_check","method":"POST"} []
[2025-03-06T13:43:13.673139+00:00] security.DEBUG: Checking for authenticator support. {"firewall_name":"login","authenticators":1} []
[2025-03-06T13:43:13.673153+00:00] security.DEBUG: Checking support on authenticator. {"firewall_name":"login","authenticator":"Symfony\\Component\\Security\\Http\\Authenticator\\Debug\\TraceableAuthenticator"} []
[2025-03-06T13:43:15.100410+00:00] doctrine.INFO: Connecting with parameters array{"host":"localhost","port":3306,"driver":"pdo_mysql","use_savepoints":true,"dbname_suffix":"_test","idle_connection_ttl":600,"user":"tima6358_amina","password":"<redacted>","driverOptions":[],"defaultTableOptions":[],"dbname":"tima6358_amina_test","serverVersion":"10.6.21-MariaDB","charset":"utf8mb4"} {"params":{"host":"localhost","port":3306,"driver":"pdo_mysql","use_savepoints":true,"dbname_suffix":"_test","idle_connection_ttl":600,"user":"tima6358_amina","password":"<redacted>","driverOptions":[],"defaultTableOptions":[],"dbname":"tima6358_amina_test","serverVersion":"10.6.21-MariaDB","charset":"utf8mb4"}} []
[2025-03-06T13:43:15.324724+00:00] request.CRITICAL: Uncaught PHP Exception Doctrine\DBAL\Exception\ConnectionException: "An exception occurred in the driver: SQLSTATE[HY000] [1045] Access denied for user 'tima6358_amina'@'localhost' (using password: YES)" at ExceptionConverter.php line 101 {"exception":"[object] (Doctrine\\DBAL\\Exception\\ConnectionException(code: 1045): An exception occurred in the driver: SQLSTATE[HY000] [1045] Access denied for user 'tima6358_amina'@'localhost' (using password: YES) at /mnt/c/Users/CDAX27/covoiturage/vendor/doctrine/dbal/src/Driver/API/MySQL/ExceptionConverter.php:101)\n[previous exception] [object] (Doctrine\\DBAL\\Driver\\PDO\\Exception(code: 1045): SQLSTATE[HY000] [1045] Access denied for user 'tima6358_amina'@'localhost' (using password: YES) at /mnt/c/Users/CDAX27/covoiturage/vendor/doctrine/dbal/src/Driver/PDO/Exception.php:24)\n[previous exception] [object] (PDOException(code: 1045): SQLSTATE[HY000] [1045] Access denied for user 'tima6358_amina'@'localhost' (using password: YES) at /mnt/c/Users/CDAX27/covoiturage/vendor/doctrine/dbal/src/Driver/PDO/MySQL/Driver.php:33)"} []
[2025-03-06T14:43:24.653603+01:00] request.INFO: Matched route "api_login". {"route":"api_login","route_parameters":{"_route":"api_login","_controller":"App\\Controller\\SecurityController::login"},"request_uri":"http://localhost/api/login_check","method":"POST"} []
[2025-03-06T14:43:24.696497+01:00] security.DEBUG: Checking for authenticator support. {"firewall_name":"login","authenticators":1} []
[2025-03-06T14:43:24.696516+01:00] security.DEBUG: Checking support on authenticator. {"firewall_name":"login","authenticator":"Symfony\\Component\\Security\\Http\\Authenticator\\Debug\\TraceableAuthenticator"} []
[2025-03-06T14:43:24.860156+01:00] doctrine.INFO: Connecting with parameters array{"host":"localhost","port":3306,"driver":"pdo_mysql","use_savepoints":true,"dbname_suffix":"_test","idle_connection_ttl":600,"user":"tima6358_amina","password":"<redacted>","driverOptions":[],"defaultTableOptions":[],"dbname":"tima6358_amina_test","serverVersion":"10.6.21-MariaDB","charset":"utf8mb4"} {"params":{"host":"localhost","port":3306,"driver":"pdo_mysql","use_savepoints":true,"dbname_suffix":"_test","idle_connection_ttl":600,"user":"tima6358_amina","password":"<redacted>","driverOptions":[],"defaultTableOptions":[],"dbname":"tima6358_amina_test","serverVersion":"10.6.21-MariaDB","charset":"utf8mb4"}} []
[2025-03-06T14:43:26.936465+01:00] request.CRITICAL: Uncaught PHP Exception Doctrine\DBAL\Exception\ConnectionException: "An exception occurred in the driver: SQLSTATE[HY000] [1045] Access denied for user 'tima6358_amina'@'localhost' (using password: YES)" at ExceptionConverter.php line 101 {"exception":"[object] (Doctrine\\DBAL\\Exception\\ConnectionException(code: 1045): An exception occurred in the driver: SQLSTATE[HY000] [1045] Access denied for user 'tima6358_amina'@'localhost' (using password: YES) at C:\\Users\\CDAX27\\covoiturage\\vendor\\doctrine\\dbal\\src\\Driver\\API\\MySQL\\ExceptionConverter.php:101)\n[previous exception] [object] (Doctrine\\DBAL\\Driver\\PDO\\Exception(code: 1045): SQLSTATE[HY000] [1045] Access denied for user 'tima6358_amina'@'localhost' (using password: YES) at C:\\Users\\CDAX27\\covoiturage\\vendor\\doctrine\\dbal\\src\\Driver\\PDO\\Exception.php:24)\n[previous exception] [object] (PDOException(code: 1045): SQLSTATE[HY000] [1045] Access denied for user 'tima6358_amina'@'localhost' (using password: YES) at C:\\Users\\CDAX27\\covoiturage\\vendor\\doctrine\\dbal\\src\\Driver\\PDO\\MySQL\\Driver.php:33)"} []
[2025-03-06T14:48:03.827725+00:00] request.INFO: Matched route "api_login". {"route":"api_login","route_parameters":{"_route":"api_login","_controller":"App\\Controller\\SecurityController::login"},"request_uri":"http://localhost/api/login_check","method":"POST"} []
[2025-03-06T14:48:04.043249+00:00] security.DEBUG: Checking for authenticator support. {"firewall_name":"login","authenticators":1} []
[2025-03-06T14:48:04.043258+00:00] security.DEBUG: Checking support on authenticator. {"firewall_name":"login","authenticator":"Symfony\\Component\\Security\\Http\\Authenticator\\Debug\\TraceableAuthenticator"} []
[2025-03-06T14:48:05.100651+00:00] doctrine.INFO: Connecting with parameters array{"host":"localhost","port":3306,"driver":"pdo_mysql","use_savepoints":true,"dbname_suffix":"_test","idle_connection_ttl":600,"user":"tima6358_amina","password":"<redacted>","driverOptions":[],"defaultTableOptions":[],"dbname":"tima6358_amina_test","serverVersion":"10.6.21-MariaDB","charset":"utf8mb4"} {"params":{"host":"localhost","port":3306,"driver":"pdo_mysql","use_savepoints":true,"dbname_suffix":"_test","idle_connection_ttl":600,"user":"tima6358_amina","password":"<redacted>","driverOptions":[],"defaultTableOptions":[],"dbname":"tima6358_amina_test","serverVersion":"10.6.21-MariaDB","charset":"utf8mb4"}} []
[2025-03-06T14:48:05.247871+00:00] request.CRITICAL: Uncaught PHP Exception Doctrine\DBAL\Exception\ConnectionException: "An exception occurred in the driver: SQLSTATE[HY000] [1045] Access denied for user 'tima6358_amina'@'localhost' (using password: YES)" at ExceptionConverter.php line 101 {"exception":"[object] (Doctrine\\DBAL\\Exception\\ConnectionException(code: 1045): An exception occurred in the driver: SQLSTATE[HY000] [1045] Access denied for user 'tima6358_amina'@'localhost' (using password: YES) at /mnt/c/Users/CDAX27/covoiturage/vendor/doctrine/dbal/src/Driver/API/MySQL/ExceptionConverter.php:101)\n[previous exception] [object] (Doctrine\\DBAL\\Driver\\PDO\\Exception(code: 1045): SQLSTATE[HY000] [1045] Access denied for user 'tima6358_amina'@'localhost' (using password: YES) at /mnt/c/Users/CDAX27/covoiturage/vendor/doctrine/dbal/src/Driver/PDO/Exception.php:24)\n[previous exception] [object] (PDOException(code: 1045): SQLSTATE[HY000] [1045] Access denied for user 'tima6358_amina'@'localhost' (using password: YES) at /mnt/c/Users/CDAX27/covoiturage/vendor/doctrine/dbal/src/Driver/PDO/MySQL/Driver.php:33)"} []
[2025-03-06T14:54:26.967054+00:00] request.INFO: Matched route "api_login". {"route":"api_login","route_parameters":{"_route":"api_login","_controller":"App\\Controller\\SecurityController::login"},"request_uri":"http://localhost/api/login_check","method":"POST"} []
[2025-03-06T14:54:27.124772+00:00] security.DEBUG: Checking for authenticator support. {"firewall_name":"login","authenticators":1} []
[2025-03-06T14:54:27.124787+00:00] security.DEBUG: Checking support on authenticator. {"firewall_name":"login","authenticator":"Symfony\\Component\\Security\\Http\\Authenticator\\Debug\\TraceableAuthenticator"} []
[2025-03-06T14:54:27.811396+00:00] doctrine.INFO: Connecting with parameters array{"host":"localhost","port":3306,"driver":"pdo_mysql","use_savepoints":true,"dbname_suffix":"_test","idle_connection_ttl":600,"user":"tima6358_amina","password":"<redacted>","driverOptions":[],"defaultTableOptions":[],"dbname":"tima6358_amina_test","serverVersion":"10.6.21-MariaDB","charset":"utf8mb4"} {"params":{"host":"localhost","port":3306,"driver":"pdo_mysql","use_savepoints":true,"dbname_suffix":"_test","idle_connection_ttl":600,"user":"tima6358_amina","password":"<redacted>","driverOptions":[],"defaultTableOptions":[],"dbname":"tima6358_amina_test","serverVersion":"10.6.21-MariaDB","charset":"utf8mb4"}} []
[2025-03-06T14:54:27.974897+00:00] request.CRITICAL: Uncaught PHP Exception Doctrine\DBAL\Exception\ConnectionException: "An exception occurred in the driver: SQLSTATE[HY000] [1045] Access denied for user 'tima6358_amina'@'localhost' (using password: YES)" at ExceptionConverter.php line 101 {"exception":"[object] (Doctrine\\DBAL\\Exception\\ConnectionException(code: 1045): An exception occurred in the driver: SQLSTATE[HY000] [1045] Access denied for user 'tima6358_amina'@'localhost' (using password: YES) at /mnt/c/Users/CDAX27/covoiturage/vendor/doctrine/dbal/src/Driver/API/MySQL/ExceptionConverter.php:101)\n[previous exception] [object] (Doctrine\\DBAL\\Driver\\PDO\\Exception(code: 1045): SQLSTATE[HY000] [1045] Access denied for user 'tima6358_amina'@'localhost' (using password: YES) at /mnt/c/Users/CDAX27/covoiturage/vendor/doctrine/dbal/src/Driver/PDO/Exception.php:24)\n[previous exception] [object] (PDOException(code: 1045): SQLSTATE[HY000] [1045] Access denied for user 'tima6358_amina'@'localhost' (using password: YES) at /mnt/c/Users/CDAX27/covoiturage/vendor/doctrine/dbal/src/Driver/PDO/MySQL/Driver.php:33)"} []
[2025-03-06T15:55:27.021179+01:00] request.INFO: Matched route "api_login". {"route":"api_login","route_parameters":{"_route":"api_login","_controller":"App\\Controller\\SecurityController::login"},"request_uri":"http://localhost/api/login_check","method":"POST"} []
[2025-03-06T15:55:27.055143+01:00] security.DEBUG: Checking for authenticator support. {"firewall_name":"login","authenticators":1} []
[2025-03-06T15:55:27.055154+01:00] security.DEBUG: Checking support on authenticator. {"firewall_name":"login","authenticator":"Symfony\\Component\\Security\\Http\\Authenticator\\Debug\\TraceableAuthenticator"} []
[2025-03-06T15:55:27.218313+01:00] doctrine.INFO: Connecting with parameters array{"host":"localhost","port":3306,"driver":"pdo_mysql","use_savepoints":true,"dbname_suffix":"_test","idle_connection_ttl":600,"user":"tima6358_amina","password":"<redacted>","driverOptions":[],"defaultTableOptions":[],"dbname":"tima6358_amina_test","serverVersion":"10.6.21-MariaDB","charset":"utf8mb4"} {"params":{"host":"localhost","port":3306,"driver":"pdo_mysql","use_savepoints":true,"dbname_suffix":"_test","idle_connection_ttl":600,"user":"tima6358_amina","password":"<redacted>","driverOptions":[],"defaultTableOptions":[],"dbname":"tima6358_amina_test","serverVersion":"10.6.21-MariaDB","charset":"utf8mb4"}} []
[2025-03-06T15:55:29.285697+01:00] request.CRITICAL: Uncaught PHP Exception Doctrine\DBAL\Exception\ConnectionException: "An exception occurred in the driver: SQLSTATE[HY000] [1045] Access denied for user 'tima6358_amina'@'localhost' (using password: YES)" at ExceptionConverter.php line 101 {"exception":"[object] (Doctrine\\DBAL\\Exception\\ConnectionException(code: 1045): An exception occurred in the driver: SQLSTATE[HY000] [1045] Access denied for user 'tima6358_amina'@'localhost' (using password: YES) at C:\\Users\\CDAX27\\covoiturage\\vendor\\doctrine\\dbal\\src\\Driver\\API\\MySQL\\ExceptionConverter.php:101)\n[previous exception] [object] (Doctrine\\DBAL\\Driver\\PDO\\Exception(code: 1045): SQLSTATE[HY000] [1045] Access denied for user 'tima6358_amina'@'localhost' (using password: YES) at C:\\Users\\CDAX27\\covoiturage\\vendor\\doctrine\\dbal\\src\\Driver\\PDO\\Exception.php:24)\n[previous exception] [object] (PDOException(code: 1045): SQLSTATE[HY000] [1045] Access denied for user 'tima6358_amina'@'localhost' (using password: YES) at C:\\Users\\CDAX27\\covoiturage\\vendor\\doctrine\\dbal\\src\\Driver\\PDO\\MySQL\\Driver.php:33)"} []
[2025-03-06T16:00:39.947040+01:00] request.INFO: Matched route "api_login". {"route":"api_login","route_parameters":{"_route":"api_login","_controller":"App\\Controller\\SecurityController::login"},"request_uri":"http://localhost/api/login_check","method":"POST"} []
[2025-03-06T16:00:40.002728+01:00] security.DEBUG: Checking for authenticator support. {"firewall_name":"login","authenticators":1} []
[2025-03-06T16:00:40.002740+01:00] security.DEBUG: Checking support on authenticator. {"firewall_name":"login","authenticator":"Symfony\\Component\\Security\\Http\\Authenticator\\Debug\\TraceableAuthenticator"} []
[2025-03-06T16:00:40.111183+01:00] doctrine.INFO: Connecting with parameters array{"use_savepoints":true,"dbname_suffix":"_test","driver":"pdo_mysql","idle_connection_ttl":600,"host":"localhost","port":3306,"user":"tima6358_amina","password":"<redacted>","driverOptions":[],"defaultTableOptions":[],"dbname":"tima6358_amina_test","serverVersion":"10.6.21-MariaDB","charset":"utf8mb4"} {"params":{"use_savepoints":true,"dbname_suffix":"_test","driver":"pdo_mysql","idle_connection_ttl":600,"host":"localhost","port":3306,"user":"tima6358_amina","password":"<redacted>","driverOptions":[],"defaultTableOptions":[],"dbname":"tima6358_amina_test","serverVersion":"10.6.21-MariaDB","charset":"utf8mb4"}} []
[2025-03-06T16:00:42.196222+01:00] request.CRITICAL: Uncaught PHP Exception Doctrine\DBAL\Exception\ConnectionException: "An exception occurred in the driver: SQLSTATE[HY000] [1045] Access denied for user 'tima6358_amina'@'localhost' (using password: YES)" at ExceptionConverter.php line 101 {"exception":"[object] (Doctrine\\DBAL\\Exception\\ConnectionException(code: 1045): An exception occurred in the driver: SQLSTATE[HY000] [1045] Access denied for user 'tima6358_amina'@'localhost' (using password: YES) at C:\\Users\\CDAX27\\covoiturage\\vendor\\doctrine\\dbal\\src\\Driver\\API\\MySQL\\ExceptionConverter.php:101)\n[previous exception] [object] (Doctrine\\DBAL\\Driver\\PDO\\Exception(code: 1045): SQLSTATE[HY000] [1045] Access denied for user 'tima6358_amina'@'localhost' (using password: YES) at C:\\Users\\CDAX27\\covoiturage\\vendor\\doctrine\\dbal\\src\\Driver\\PDO\\Exception.php:24)\n[previous exception] [object] (PDOException(code: 1045): SQLSTATE[HY000] [1045] Access denied for user 'tima6358_amina'@'localhost' (using password: YES) at C:\\Users\\CDAX27\\covoiturage\\vendor\\doctrine\\dbal\\src\\Driver\\PDO\\MySQL\\Driver.php:33)"} []
[2025-03-06T16:00:43.887948+01:00] request.INFO: Matched route "api_login". {"route":"api_login","route_parameters":{"_route":"api_login","_controller":"App\\Controller\\SecurityController::login"},"request_uri":"http://localhost/api/login_check","method":"POST"} []
[2025-03-06T16:00:43.888272+01:00] security.DEBUG: Checking for authenticator support. {"firewall_name":"login","authenticators":1} []
[2025-03-06T16:00:43.888277+01:00] security.DEBUG: Checking support on authenticator. {"firewall_name":"login","authenticator":"Symfony\\Component\\Security\\Http\\Authenticator\\Debug\\TraceableAuthenticator"} []
[2025-03-06T16:00:43.890678+01:00] doctrine.INFO: Connecting with parameters array{"use_savepoints":true,"dbname_suffix":"_test","driver":"pdo_mysql","idle_connection_ttl":600,"host":"localhost","port":3306,"user":"tima6358_amina","password":"<redacted>","driverOptions":[],"defaultTableOptions":[],"dbname":"tima6358_amina_test","serverVersion":"10.6.21-MariaDB","charset":"utf8mb4"} {"params":{"use_savepoints":true,"dbname_suffix":"_test","driver":"pdo_mysql","idle_connection_ttl":600,"host":"localhost","port":3306,"user":"tima6358_amina","password":"<redacted>","driverOptions":[],"defaultTableOptions":[],"dbname":"tima6358_amina_test","serverVersion":"10.6.21-MariaDB","charset":"utf8mb4"}} []
[2025-03-06T16:00:45.913058+01:00] request.CRITICAL: Uncaught PHP Exception Doctrine\DBAL\Exception\ConnectionException: "An exception occurred in the driver: SQLSTATE[HY000] [1045] Access denied for user 'tima6358_amina'@'localhost' (using password: YES)" at ExceptionConverter.php line 101 {"exception":"[object] (Doctrine\\DBAL\\Exception\\ConnectionException(code: 1045): An exception occurred in the driver: SQLSTATE[HY000] [1045] Access denied for user 'tima6358_amina'@'localhost' (using password: YES) at C:\\Users\\CDAX27\\covoiturage\\vendor\\doctrine\\dbal\\src\\Driver\\API\\MySQL\\ExceptionConverter.php:101)\n[previous exception] [object] (Doctrine\\DBAL\\Driver\\PDO\\Exception(code: 1045): SQLSTATE[HY000] [1045] Access denied for user 'tima6358_amina'@'localhost' (using password: YES) at C:\\Users\\CDAX27\\covoiturage\\vendor\\doctrine\\dbal\\src\\Driver\\PDO\\Exception.php:24)\n[previous exception] [object] (PDOException(code: 1045): SQLSTATE[HY000] [1045] Access denied for user 'tima6358_amina'@'localhost' (using password: YES) at C:\\Users\\CDAX27\\covoiturage\\vendor\\doctrine\\dbal\\src\\Driver\\PDO\\MySQL\\Driver.php:33)"} []
[2025-03-06T16:05:32.838011+01:00] request.INFO: Matched route "api_login". {"route":"api_login","route_parameters":{"_route":"api_login","_controller":"App\\Controller\\SecurityController::login"},"request_uri":"http://localhost/api/login_check","method":"POST"} []
[2025-03-06T16:05:32.896363+01:00] security.DEBUG: Checking for authenticator support. {"firewall_name":"login","authenticators":1} []
[2025-03-06T16:05:32.896374+01:00] security.DEBUG: Checking support on authenticator. {"firewall_name":"login","authenticator":"Symfony\\Component\\Security\\Http\\Authenticator\\Debug\\TraceableAuthenticator"} []
[2025-03-06T16:05:33.018697+01:00] doctrine.INFO: Connecting with parameters array{"use_savepoints":true,"dbname_suffix":"_test","driver":"pdo_mysql","idle_connection_ttl":600,"host":"localhost","port":3306,"user":"tima6358_amina","password":"<redacted>","driverOptions":[],"defaultTableOptions":[],"dbname":"tima6358_amina_test","serverVersion":"10.6.21-MariaDB","charset":"utf8mb4"} {"params":{"use_savepoints":true,"dbname_suffix":"_test","driver":"pdo_mysql","idle_connection_ttl":600,"host":"localhost","port":3306,"user":"tima6358_amina","password":"<redacted>","driverOptions":[],"defaultTableOptions":[],"dbname":"tima6358_amina_test","serverVersion":"10.6.21-MariaDB","charset":"utf8mb4"}} []
[2025-03-06T16:05:35.108962+01:00] request.CRITICAL: Uncaught PHP Exception Doctrine\DBAL\Exception\ConnectionException: "An exception occurred in the driver: SQLSTATE[HY000] [1045] Access denied for user 'tima6358_amina'@'localhost' (using password: YES)" at ExceptionConverter.php line 101 {"exception":"[object] (Doctrine\\DBAL\\Exception\\ConnectionException(code: 1045): An exception occurred in the driver: SQLSTATE[HY000] [1045] Access denied for user 'tima6358_amina'@'localhost' (using password: YES) at C:\\Users\\CDAX27\\covoiturage\\vendor\\doctrine\\dbal\\src\\Driver\\API\\MySQL\\ExceptionConverter.php:101)\n[previous exception] [object] (Doctrine\\DBAL\\Driver\\PDO\\Exception(code: 1045): SQLSTATE[HY000] [1045] Access denied for user 'tima6358_amina'@'localhost' (using password: YES) at C:\\Users\\CDAX27\\covoiturage\\vendor\\doctrine\\dbal\\src\\Driver\\PDO\\Exception.php:24)\n[previous exception] [object] (PDOException(code: 1045): SQLSTATE[HY000] [1045] Access denied for user 'tima6358_amina'@'localhost' (using password: YES) at C:\\Users\\CDAX27\\covoiturage\\vendor\\doctrine\\dbal\\src\\Driver\\PDO\\MySQL\\Driver.php:33)"} []
[2025-03-06T16:05:36.397200+01:00] request.INFO: Matched route "api_login". {"route":"api_login","route_parameters":{"_route":"api_login","_controller":"App\\Controller\\SecurityController::login"},"request_uri":"http://localhost/api/login_check","method":"POST"} []
[2025-03-06T16:05:36.397921+01:00] security.DEBUG: Checking for authenticator support. {"firewall_name":"login","authenticators":1} []
[2025-03-06T16:05:36.397929+01:00] security.DEBUG: Checking support on authenticator. {"firewall_name":"login","authenticator":"Symfony\\Component\\Security\\Http\\Authenticator\\Debug\\TraceableAuthenticator"} []
[2025-03-06T16:05:36.399685+01:00] doctrine.INFO: Connecting with parameters array{"use_savepoints":true,"dbname_suffix":"_test","driver":"pdo_mysql","idle_connection_ttl":600,"host":"localhost","port":3306,"user":"tima6358_amina","password":"<redacted>","driverOptions":[],"defaultTableOptions":[],"dbname":"tima6358_amina_test","serverVersion":"10.6.21-MariaDB","charset":"utf8mb4"} {"params":{"use_savepoints":true,"dbname_suffix":"_test","driver":"pdo_mysql","idle_connection_ttl":600,"host":"localhost","port":3306,"user":"tima6358_amina","password":"<redacted>","driverOptions":[],"defaultTableOptions":[],"dbname":"tima6358_amina_test","serverVersion":"10.6.21-MariaDB","charset":"utf8mb4"}} []
[2025-03-06T16:05:38.465871+01:00] request.CRITICAL: Uncaught PHP Exception Doctrine\DBAL\Exception\ConnectionException: "An exception occurred in the driver: SQLSTATE[HY000] [1045] Access denied for user 'tima6358_amina'@'localhost' (using password: YES)" at ExceptionConverter.php line 101 {"exception":"[object] (Doctrine\\DBAL\\Exception\\ConnectionException(code: 1045): An exception occurred in the driver: SQLSTATE[HY000] [1045] Access denied for user 'tima6358_amina'@'localhost' (using password: YES) at C:\\Users\\CDAX27\\covoiturage\\vendor\\doctrine\\dbal\\src\\Driver\\API\\MySQL\\ExceptionConverter.php:101)\n[previous exception] [object] (Doctrine\\DBAL\\Driver\\PDO\\Exception(code: 1045): SQLSTATE[HY000] [1045] Access denied for user 'tima6358_amina'@'localhost' (using password: YES) at C:\\Users\\CDAX27\\covoiturage\\vendor\\doctrine\\dbal\\src\\Driver\\PDO\\Exception.php:24)\n[previous exception] [object] (PDOException(code: 1045): SQLSTATE[HY000] [1045] Access denied for user 'tima6358_amina'@'localhost' (using password: YES) at C:\\Users\\CDAX27\\covoiturage\\vendor\\doctrine\\dbal\\src\\Driver\\PDO\\MySQL\\Driver.php:33)"} []
[2025-03-06T16:07:46.970932+01:00] request.INFO: Matched route "api_login". {"route":"api_login","route_parameters":{"_route":"api_login","_controller":"App\\Controller\\SecurityController::login"},"request_uri":"http://localhost/api/login_check","method":"POST"} []
[2025-03-06T16:07:47.054441+01:00] security.DEBUG: Checking for authenticator support. {"firewall_name":"login","authenticators":1} []
[2025-03-06T16:07:47.054452+01:00] security.DEBUG: Checking support on authenticator. {"firewall_name":"login","authenticator":"Symfony\\Component\\Security\\Http\\Authenticator\\Debug\\TraceableAuthenticator"} []
[2025-03-06T16:07:47.178750+01:00] doctrine.INFO: Connecting with parameters array{"use_savepoints":true,"dbname_suffix":"_test","driver":"pdo_mysql","idle_connection_ttl":600,"host":"localhost","port":3306,"user":"tima6358_amina","password":"<redacted>","driverOptions":[],"defaultTableOptions":[],"dbname":"tima6358_amina_test","serverVersion":"10.6.21-MariaDB","charset":"utf8mb4"} {"params":{"use_savepoints":true,"dbname_suffix":"_test","driver":"pdo_mysql","idle_connection_ttl":600,"host":"localhost","port":3306,"user":"tima6358_amina","password":"<redacted>","driverOptions":[],"defaultTableOptions":[],"dbname":"tima6358_amina_test","serverVersion":"10.6.21-MariaDB","charset":"utf8mb4"}} []
[2025-03-06T16:07:49.264044+01:00] request.CRITICAL: Uncaught PHP Exception Doctrine\DBAL\Exception\ConnectionException: "An exception occurred in the driver: SQLSTATE[HY000] [1045] Access denied for user 'tima6358_amina'@'localhost' (using password: YES)" at ExceptionConverter.php line 101 {"exception":"[object] (Doctrine\\DBAL\\Exception\\ConnectionException(code: 1045): An exception occurred in the driver: SQLSTATE[HY000] [1045] Access denied for user 'tima6358_amina'@'localhost' (using password: YES) at C:\\Users\\CDAX27\\covoiturage\\vendor\\doctrine\\dbal\\src\\Driver\\API\\MySQL\\ExceptionConverter.php:101)\n[previous exception] [object] (Doctrine\\DBAL\\Driver\\PDO\\Exception(code: 1045): SQLSTATE[HY000] [1045] Access denied for user 'tima6358_amina'@'localhost' (using password: YES) at C:\\Users\\CDAX27\\covoiturage\\vendor\\doctrine\\dbal\\src\\Driver\\PDO\\Exception.php:24)\n[previous exception] [object] (PDOException(code: 1045): SQLSTATE[HY000] [1045] Access denied for user 'tima6358_amina'@'localhost' (using password: YES) at C:\\Users\\CDAX27\\covoiturage\\vendor\\doctrine\\dbal\\src\\Driver\\PDO\\MySQL\\Driver.php:33)"} []
[2025-03-06T16:07:50.514039+01:00] request.INFO: Matched route "api_login". {"route":"api_login","route_parameters":{"_route":"api_login","_controller":"App\\Controller\\SecurityController::login"},"request_uri":"http://localhost/api/login_check","method":"POST"} []
[2025-03-06T16:07:50.516796+01:00] security.DEBUG: Checking for authenticator support. {"firewall_name":"login","authenticators":1} []
[2025-03-06T16:07:50.516806+01:00] security.DEBUG: Checking support on authenticator. {"firewall_name":"login","authenticator":"Symfony\\Component\\Security\\Http\\Authenticator\\Debug\\TraceableAuthenticator"} []
[2025-03-06T16:07:50.518733+01:00] doctrine.INFO: Connecting with parameters array{"use_savepoints":true,"dbname_suffix":"_test","driver":"pdo_mysql","idle_connection_ttl":600,"host":"localhost","port":3306,"user":"tima6358_amina","password":"<redacted>","driverOptions":[],"defaultTableOptions":[],"dbname":"tima6358_amina_test","serverVersion":"10.6.21-MariaDB","charset":"utf8mb4"} {"params":{"use_savepoints":true,"dbname_suffix":"_test","driver":"pdo_mysql","idle_connection_ttl":600,"host":"localhost","port":3306,"user":"tima6358_amina","password":"<redacted>","driverOptions":[],"defaultTableOptions":[],"dbname":"tima6358_amina_test","serverVersion":"10.6.21-MariaDB","charset":"utf8mb4"}} []
[2025-03-06T16:07:52.576200+01:00] request.CRITICAL: Uncaught PHP Exception Doctrine\DBAL\Exception\ConnectionException: "An exception occurred in the driver: SQLSTATE[HY000] [1045] Access denied for user 'tima6358_amina'@'localhost' (using password: YES)" at ExceptionConverter.php line 101 {"exception":"[object] (Doctrine\\DBAL\\Exception\\ConnectionException(code: 1045): An exception occurred in the driver: SQLSTATE[HY000] [1045] Access denied for user 'tima6358_amina'@'localhost' (using password: YES) at C:\\Users\\CDAX27\\covoiturage\\vendor\\doctrine\\dbal\\src\\Driver\\API\\MySQL\\ExceptionConverter.php:101)\n[previous exception] [object] (Doctrine\\DBAL\\Driver\\PDO\\Exception(code: 1045): SQLSTATE[HY000] [1045] Access denied for user 'tima6358_amina'@'localhost' (using password: YES) at C:\\Users\\CDAX27\\covoiturage\\vendor\\doctrine\\dbal\\src\\Driver\\PDO\\Exception.php:24)\n[previous exception] [object] (PDOException(code: 1045): SQLSTATE[HY000] [1045] Access denied for user 'tima6358_amina'@'localhost' (using password: YES) at C:\\Users\\CDAX27\\covoiturage\\vendor\\doctrine\\dbal\\src\\Driver\\PDO\\MySQL\\Driver.php:33)"} []
[2025-03-06T16:09:45.215325+01:00] request.INFO: Matched route "api_login". {"route":"api_login","route_parameters":{"_route":"api_login","_controller":"App\\Controller\\SecurityController::login"},"request_uri":"http://localhost/api/login_check","method":"POST"} []
[2025-03-06T16:09:45.311862+01:00] security.DEBUG: Checking for authenticator support. {"firewall_name":"login","authenticators":1} []
[2025-03-06T16:09:45.311874+01:00] security.DEBUG: Checking support on authenticator. {"firewall_name":"login","authenticator":"Symfony\\Component\\Security\\Http\\Authenticator\\Debug\\TraceableAuthenticator"} []
[2025-03-06T16:09:45.491393+01:00] doctrine.INFO: Connecting with parameters array{"use_savepoints":true,"dbname_suffix":"_test","driver":"pdo_mysql","idle_connection_ttl":600,"host":"localhost","port":3306,"user":"tima6358_amina","password":"<redacted>","driverOptions":[],"defaultTableOptions":[],"dbname":"tima6358_amina_test","serverVersion":"10.6.21-MariaDB","charset":"utf8mb4"} {"params":{"use_savepoints":true,"dbname_suffix":"_test","driver":"pdo_mysql","idle_connection_ttl":600,"host":"localhost","port":3306,"user":"tima6358_amina","password":"<redacted>","driverOptions":[],"defaultTableOptions":[],"dbname":"tima6358_amina_test","serverVersion":"10.6.21-MariaDB","charset":"utf8mb4"}} []
[2025-03-06T16:09:47.573775+01:00] request.CRITICAL: Uncaught PHP Exception Doctrine\DBAL\Exception\ConnectionException: "An exception occurred in the driver: SQLSTATE[HY000] [1045] Access denied for user 'tima6358_amina'@'localhost' (using password: YES)" at ExceptionConverter.php line 101 {"exception":"[object] (Doctrine\\DBAL\\Exception\\ConnectionException(code: 1045): An exception occurred in the driver: SQLSTATE[HY000] [1045] Access denied for user 'tima6358_amina'@'localhost' (using password: YES) at C:\\Users\\CDAX27\\covoiturage\\vendor\\doctrine\\dbal\\src\\Driver\\API\\MySQL\\ExceptionConverter.php:101)\n[previous exception] [object] (Doctrine\\DBAL\\Driver\\PDO\\Exception(code: 1045): SQLSTATE[HY000] [1045] Access denied for user 'tima6358_amina'@'localhost' (using password: YES) at C:\\Users\\CDAX27\\covoiturage\\vendor\\doctrine\\dbal\\src\\Driver\\PDO\\Exception.php:24)\n[previous exception] [object] (PDOException(code: 1045): SQLSTATE[HY000] [1045] Access denied for user 'tima6358_amina'@'localhost' (using password: YES) at C:\\Users\\CDAX27\\covoiturage\\vendor\\doctrine\\dbal\\src\\Driver\\PDO\\MySQL\\Driver.php:33)"} []
[2025-03-06T16:09:48.973756+01:00] request.INFO: Matched route "api_login". {"route":"api_login","route_parameters":{"_route":"api_login","_controller":"App\\Controller\\SecurityController::login"},"request_uri":"http://localhost/api/login_check","method":"POST"} []
[2025-03-06T16:09:48.974415+01:00] security.DEBUG: Checking for authenticator support. {"firewall_name":"login","authenticators":1} []
[2025-03-06T16:09:48.974422+01:00] security.DEBUG: Checking support on authenticator. {"firewall_name":"login","authenticator":"Symfony\\Component\\Security\\Http\\Authenticator\\Debug\\TraceableAuthenticator"} []
[2025-03-06T16:09:48.976138+01:00] doctrine.INFO: Connecting with parameters array{"use_savepoints":true,"dbname_suffix":"_test","driver":"pdo_mysql","idle_connection_ttl":600,"host":"localhost","port":3306,"user":"tima6358_amina","password":"<redacted>","driverOptions":[],"defaultTableOptions":[],"dbname":"tima6358_amina_test","serverVersion":"10.6.21-MariaDB","charset":"utf8mb4"} {"params":{"use_savepoints":true,"dbname_suffix":"_test","driver":"pdo_mysql","idle_connection_ttl":600,"host":"localhost","port":3306,"user":"tima6358_amina","password":"<redacted>","driverOptions":[],"defaultTableOptions":[],"dbname":"tima6358_amina_test","serverVersion":"10.6.21-MariaDB","charset":"utf8mb4"}} []
[2025-03-06T16:09:51.009157+01:00] request.CRITICAL: Uncaught PHP Exception Doctrine\DBAL\Exception\ConnectionException: "An exception occurred in the driver: SQLSTATE[HY000] [1045] Access denied for user 'tima6358_amina'@'localhost' (using password: YES)" at ExceptionConverter.php line 101 {"exception":"[object] (Doctrine\\DBAL\\Exception\\ConnectionException(code: 1045): An exception occurred in the driver: SQLSTATE[HY000] [1045] Access denied for user 'tima6358_amina'@'localhost' (using password: YES) at C:\\Users\\CDAX27\\covoiturage\\vendor\\doctrine\\dbal\\src\\Driver\\API\\MySQL\\ExceptionConverter.php:101)\n[previous exception] [object] (Doctrine\\DBAL\\Driver\\PDO\\Exception(code: 1045): SQLSTATE[HY000] [1045] Access denied for user 'tima6358_amina'@'localhost' (using password: YES) at C:\\Users\\CDAX27\\covoiturage\\vendor\\doctrine\\dbal\\src\\Driver\\PDO\\Exception.php:24)\n[previous exception] [object] (PDOException(code: 1045): SQLSTATE[HY000] [1045] Access denied for user 'tima6358_amina'@'localhost' (using password: YES) at C:\\Users\\CDAX27\\covoiturage\\vendor\\doctrine\\dbal\\src\\Driver\\PDO\\MySQL\\Driver.php:33)"} []
[2025-03-06T16:21:04.342861+01:00] doctrine.INFO: Connecting with parameters array{"use_savepoints":true,"dbname_suffix":"_test","driver":"pdo_sqlite","idle_connection_ttl":600,"host":"localhost","port":null,"user":"root","password":null,"driverOptions":[],"defaultTableOptions":[],"path":"%kernel.project_dir%/var/data.db","charset":"utf8"} {"params":{"use_savepoints":true,"dbname_suffix":"_test","driver":"pdo_sqlite","idle_connection_ttl":600,"host":"localhost","port":null,"user":"root","password":null,"driverOptions":[],"defaultTableOptions":[],"path":"%kernel.project_dir%/var/data.db","charset":"utf8"}} []
[2025-03-06T16:21:04.372450+01:00] console.CRITICAL: Error thrown while running command "doctrine:migrations:diff --env=test". Message: "An exception occurred in the driver: SQLSTATE[HY000] [14] unable to open database file" {"exception":"[object] (Doctrine\\DBAL\\Exception\\ConnectionException(code: 14): An exception occurred in the driver: SQLSTATE[HY000] [14] unable to open database file at C:\\Users\\CDAX27\\covoiturage\\vendor\\doctrine\\dbal\\src\\Driver\\API\\SQLite\\ExceptionConverter.php:76)\n[previous exception] [object] (Doctrine\\DBAL\\Driver\\PDO\\Exception(code: 14): SQLSTATE[HY000] [14] unable to open database file at C:\\Users\\CDAX27\\covoiturage\\vendor\\doctrine\\dbal\\src\\Driver\\PDO\\Exception.php:24)\n[previous exception] [object] (PDOException(code: 14): SQLSTATE[HY000] [14] unable to open database file at C:\\Users\\CDAX27\\covoiturage\\vendor\\doctrine\\dbal\\src\\Driver\\PDO\\SQLite\\Driver.php:43)","command":"doctrine:migrations:diff --env=test","message":"An exception occurred in the driver: SQLSTATE[HY000] [14] unable to open database file"} []
[2025-03-06T16:21:04.380690+01:00] console.DEBUG: Command "doctrine:migrations:diff --env=test" exited with code "14" {"command":"doctrine:migrations:diff --env=test","code":14} []
[2025-03-06T16:22:47.753678+01:00] doctrine.INFO: Connecting with parameters array{"use_savepoints":true,"dbname_suffix":"_test","driver":"pdo_sqlite","idle_connection_ttl":600,"host":"localhost","port":null,"user":"root","password":null,"driverOptions":[],"defaultTableOptions":[],"path":"%kernel.project_dir%/var/data.db","charset":"utf8"} {"params":{"use_savepoints":true,"dbname_suffix":"_test","driver":"pdo_sqlite","idle_connection_ttl":600,"host":"localhost","port":null,"user":"root","password":null,"driverOptions":[],"defaultTableOptions":[],"path":"%kernel.project_dir%/var/data.db","charset":"utf8"}} []
[2025-03-06T16:22:47.773135+01:00] console.CRITICAL: Error thrown while running command "doctrine:migrations:diff --env=test". Message: "An exception occurred in the driver: SQLSTATE[HY000] [14] unable to open database file" {"exception":"[object] (Doctrine\\DBAL\\Exception\\ConnectionException(code: 14): An exception occurred in the driver: SQLSTATE[HY000] [14] unable to open database file at C:\\Users\\CDAX27\\covoiturage\\vendor\\doctrine\\dbal\\src\\Driver\\API\\SQLite\\ExceptionConverter.php:76)\n[previous exception] [object] (Doctrine\\DBAL\\Driver\\PDO\\Exception(code: 14): SQLSTATE[HY000] [14] unable to open database file at C:\\Users\\CDAX27\\covoiturage\\vendor\\doctrine\\dbal\\src\\Driver\\PDO\\Exception.php:24)\n[previous exception] [object] (PDOException(code: 14): SQLSTATE[HY000] [14] unable to open database file at C:\\Users\\CDAX27\\covoiturage\\vendor\\doctrine\\dbal\\src\\Driver\\PDO\\SQLite\\Driver.php:43)","command":"doctrine:migrations:diff --env=test","message":"An exception occurred in the driver: SQLSTATE[HY000] [14] unable to open database file"} []
[2025-03-06T16:22:47.779512+01:00] console.DEBUG: Command "doctrine:migrations:diff --env=test" exited with code "14" {"command":"doctrine:migrations:diff --env=test","code":14} []
[2025-03-06T16:25:00.533675+01:00] doctrine.INFO: Connecting with parameters array{"use_savepoints":true,"dbname_suffix":"_test","driver":"pdo_sqlite","idle_connection_ttl":600,"host":"localhost","port":null,"user":"root","password":null,"driverOptions":[],"defaultTableOptions":[],"path":"%kernel.project_dir%/var/test.db","charset":"utf8"} {"params":{"use_savepoints":true,"dbname_suffix":"_test","driver":"pdo_sqlite","idle_connection_ttl":600,"host":"localhost","port":null,"user":"root","password":null,"driverOptions":[],"defaultTableOptions":[],"path":"%kernel.project_dir%/var/test.db","charset":"utf8"}} []
[2025-03-06T16:25:00.552219+01:00] console.CRITICAL: Error thrown while running command "doctrine:database:create --env=test". Message: "An exception occurred in the driver: SQLSTATE[HY000] [14] unable to open database file" {"exception":"[object] (Doctrine\\DBAL\\Exception\\ConnectionException(code: 14): An exception occurred in the driver: SQLSTATE[HY000] [14] unable to open database file at C:\\Users\\CDAX27\\covoiturage\\vendor\\doctrine\\dbal\\src\\Driver\\API\\SQLite\\ExceptionConverter.php:76)\n[previous exception] [object] (Doctrine\\DBAL\\Driver\\PDO\\Exception(code: 14): SQLSTATE[HY000] [14] unable to open database file at C:\\Users\\CDAX27\\covoiturage\\vendor\\doctrine\\dbal\\src\\Driver\\PDO\\Exception.php:24)\n[previous exception] [object] (PDOException(code: 14): SQLSTATE[HY000] [14] unable to open database file at C:\\Users\\CDAX27\\covoiturage\\vendor\\doctrine\\dbal\\src\\Driver\\PDO\\SQLite\\Driver.php:43)","command":"doctrine:database:create --env=test","message":"An exception occurred in the driver: SQLSTATE[HY000] [14] unable to open database file"} []
[2025-03-06T16:25:00.559816+01:00] console.DEBUG: Command "doctrine:database:create --env=test" exited with code "14" {"command":"doctrine:database:create --env=test","code":14} []
[2025-03-07T07:50:01.262644+00:00] doctrine.INFO: Connecting with parameters array{"use_savepoints":true,"dbname_suffix":"_test","driver":"pdo_sqlite","idle_connection_ttl":600,"host":"localhost","port":null,"user":"root","password":null,"driverOptions":[],"defaultTableOptions":[],"path":"%kernel.project_dir%/var/test.db","charset":"utf8"} {"params":{"use_savepoints":true,"dbname_suffix":"_test","driver":"pdo_sqlite","idle_connection_ttl":600,"host":"localhost","port":null,"user":"root","password":null,"driverOptions":[],"defaultTableOptions":[],"path":"%kernel.project_dir%/var/test.db","charset":"utf8"}} []
[2025-03-07T07:50:01.354732+00:00] console.CRITICAL: Error thrown while running command "doctrine:database:create --env=test". Message: "An exception occurred in the driver: could not find driver" {"exception":"[object] (Doctrine\\DBAL\\Exception\\DriverException(code: 0): An exception occurred in the driver: could not find driver at /mnt/c/Users/CDAX27/covoiturage/vendor/doctrine/dbal/src/Driver/API/SQLite/ExceptionConverter.php:83)\n[previous exception] [object] (Doctrine\\DBAL\\Driver\\PDO\\Exception(code: 0): could not find driver at /mnt/c/Users/CDAX27/covoiturage/vendor/doctrine/dbal/src/Driver/PDO/Exception.php:24)\n[previous exception] [object] (PDOException(code: 0): could not find driver at /mnt/c/Users/CDAX27/covoiturage/vendor/doctrine/dbal/src/Driver/PDO/SQLite/Driver.php:43)","command":"doctrine:database:create --env=test","message":"An exception occurred in the driver: could not find driver"} []
[2025-03-07T07:50:01.404413+00:00] console.DEBUG: Command "doctrine:database:create --env=test" exited with code "1" {"command":"doctrine:database:create --env=test","code":1} []
[2025-03-07T07:51:42.007063+00:00] doctrine.INFO: Connecting with parameters array{"use_savepoints":true,"dbname_suffix":"_test","driver":"pdo_sqlite","idle_connection_ttl":600,"host":"localhost","port":null,"user":"root","password":null,"driverOptions":[],"defaultTableOptions":[],"path":"%kernel.project_dir%/var/test.db","charset":"utf8"} {"params":{"use_savepoints":true,"dbname_suffix":"_test","driver":"pdo_sqlite","idle_connection_ttl":600,"host":"localhost","port":null,"user":"root","password":null,"driverOptions":[],"defaultTableOptions":[],"path":"%kernel.project_dir%/var/test.db","charset":"utf8"}} []
[2025-03-07T07:51:42.092142+00:00] console.CRITICAL: Error thrown while running command "doctrine:database:create --env=test". Message: "An exception occurred in the driver: SQLSTATE[HY000] [14] unable to open database file" {"exception":"[object] (Doctrine\\DBAL\\Exception\\ConnectionException(code: 14): An exception occurred in the driver: SQLSTATE[HY000] [14] unable to open database file at /mnt/c/Users/CDAX27/covoiturage/vendor/doctrine/dbal/src/Driver/API/SQLite/ExceptionConverter.php:76)\n[previous exception] [object] (Doctrine\\DBAL\\Driver\\PDO\\Exception(code: 14): SQLSTATE[HY000] [14] unable to open database file at /mnt/c/Users/CDAX27/covoiturage/vendor/doctrine/dbal/src/Driver/PDO/Exception.php:24)\n[previous exception] [object] (PDOException(code: 14): SQLSTATE[HY000] [14] unable to open database file at /mnt/c/Users/CDAX27/covoiturage/vendor/doctrine/dbal/src/Driver/PDO/SQLite/Driver.php:43)","command":"doctrine:database:create --env=test","message":"An exception occurred in the driver: SQLSTATE[HY000] [14] unable to open database file"} []
[2025-03-07T07:51:42.117617+00:00] console.DEBUG: Command "doctrine:database:create --env=test" exited with code "14" {"command":"doctrine:database:create --env=test","code":14} []
[2025-03-07T07:54:05.335850+00:00] doctrine.INFO: Connecting with parameters array{"use_savepoints":true,"dbname_suffix":"_test","driver":"pdo_sqlite","idle_connection_ttl":600,"host":"localhost","port":null,"user":"root","password":null,"driverOptions":[],"defaultTableOptions":[],"path":"%kernel.project_dir%/var/test.db","charset":"utf8"} {"params":{"use_savepoints":true,"dbname_suffix":"_test","driver":"pdo_sqlite","idle_connection_ttl":600,"host":"localhost","port":null,"user":"root","password":null,"driverOptions":[],"defaultTableOptions":[],"path":"%kernel.project_dir%/var/test.db","charset":"utf8"}} []
[2025-03-07T07:54:05.420494+00:00] console.CRITICAL: Error thrown while running command "doctrine:database:create --env=test". Message: "An exception occurred in the driver: SQLSTATE[HY000] [14] unable to open database file" {"exception":"[object] (Doctrine\\DBAL\\Exception\\ConnectionException(code: 14): An exception occurred in the driver: SQLSTATE[HY000] [14] unable to open database file at /mnt/c/Users/CDAX27/covoiturage/vendor/doctrine/dbal/src/Driver/API/SQLite/ExceptionConverter.php:76)\n[previous exception] [object] (Doctrine\\DBAL\\Driver\\PDO\\Exception(code: 14): SQLSTATE[HY000] [14] unable to open database file at /mnt/c/Users/CDAX27/covoiturage/vendor/doctrine/dbal/src/Driver/PDO/Exception.php:24)\n[previous exception] [object] (PDOException(code: 14): SQLSTATE[HY000] [14] unable to open database file at /mnt/c/Users/CDAX27/covoiturage/vendor/doctrine/dbal/src/Driver/PDO/SQLite/Driver.php:43)","command":"doctrine:database:create --env=test","message":"An exception occurred in the driver: SQLSTATE[HY000] [14] unable to open database file"} []
[2025-03-07T07:54:05.447055+00:00] console.DEBUG: Command "doctrine:database:create --env=test" exited with code "14" {"command":"doctrine:database:create --env=test","code":14} []
[2025-03-07T07:54:22.566052+00:00] doctrine.INFO: Connecting with parameters array{"use_savepoints":true,"dbname_suffix":"_test","driver":"pdo_sqlite","idle_connection_ttl":600,"host":"localhost","port":null,"user":"root","password":null,"driverOptions":[],"defaultTableOptions":[],"path":"%kernel.project_dir%/var/test.db","charset":"utf8"} {"params":{"use_savepoints":true,"dbname_suffix":"_test","driver":"pdo_sqlite","idle_connection_ttl":600,"host":"localhost","port":null,"user":"root","password":null,"driverOptions":[],"defaultTableOptions":[],"path":"%kernel.project_dir%/var/test.db","charset":"utf8"}} []
[2025-03-07T07:54:22.753304+00:00] console.CRITICAL: Error thrown while running command "doctrine:migrations:migrate --no-interaction --env=test". Message: "An exception occurred in the driver: SQLSTATE[HY000] [14] unable to open database file" {"exception":"[object] (Doctrine\\DBAL\\Exception\\ConnectionException(code: 14): An exception occurred in the driver: SQLSTATE[HY000] [14] unable to open database file at /mnt/c/Users/CDAX27/covoiturage/vendor/doctrine/dbal/src/Driver/API/SQLite/ExceptionConverter.php:76)\n[previous exception] [object] (Doctrine\\DBAL\\Driver\\PDO\\Exception(code: 14): SQLSTATE[HY000] [14] unable to open database file at /mnt/c/Users/CDAX27/covoiturage/vendor/doctrine/dbal/src/Driver/PDO/Exception.php:24)\n[previous exception] [object] (PDOException(code: 14): SQLSTATE[HY000] [14] unable to open database file at /mnt/c/Users/CDAX27/covoiturage/vendor/doctrine/dbal/src/Driver/PDO/SQLite/Driver.php:43)","command":"doctrine:migrations:migrate --no-interaction --env=test","message":"An exception occurred in the driver: SQLSTATE[HY000] [14] unable to open database file"} []
[2025-03-07T07:54:22.824585+00:00] console.DEBUG: Command "doctrine:migrations:migrate --no-interaction --env=test" exited with code "14" {"command":"doctrine:migrations:migrate --no-interaction --env=test","code":14} []
[2025-03-07T08:00:22.890195+00:00] doctrine.INFO: Connecting with parameters array{"use_savepoints":true,"driver":"pdo_sqlite","path":"%kernel.project_dir%/var/test.db","memory":false,"idle_connection_ttl":600,"host":"localhost","port":null,"user":"root","password":null,"driverOptions":[],"defaultTableOptions":[],"charset":"utf8"} {"params":{"use_savepoints":true,"driver":"pdo_sqlite","path":"%kernel.project_dir%/var/test.db","memory":false,"idle_connection_ttl":600,"host":"localhost","port":null,"user":"root","password":null,"driverOptions":[],"defaultTableOptions":[],"charset":"utf8"}} []
[2025-03-07T08:00:23.015818+00:00] console.CRITICAL: Error thrown while running command "doctrine:database:create --env=test". Message: "An exception occurred in the driver: SQLSTATE[HY000] [14] unable to open database file" {"exception":"[object] (Doctrine\\DBAL\\Exception\\ConnectionException(code: 14): An exception occurred in the driver: SQLSTATE[HY000] [14] unable to open database file at /mnt/c/Users/CDAX27/covoiturage/vendor/doctrine/dbal/src/Driver/API/SQLite/ExceptionConverter.php:76)\n[previous exception] [object] (Doctrine\\DBAL\\Driver\\PDO\\Exception(code: 14): SQLSTATE[HY000] [14] unable to open database file at /mnt/c/Users/CDAX27/covoiturage/vendor/doctrine/dbal/src/Driver/PDO/Exception.php:24)\n[previous exception] [object] (PDOException(code: 14): SQLSTATE[HY000] [14] unable to open database file at /mnt/c/Users/CDAX27/covoiturage/vendor/doctrine/dbal/src/Driver/PDO/SQLite/Driver.php:43)","command":"doctrine:database:create --env=test","message":"An exception occurred in the driver: SQLSTATE[HY000] [14] unable to open database file"} []
[2025-03-07T08:00:23.053705+00:00] console.DEBUG: Command "doctrine:database:create --env=test" exited with code "14" {"command":"doctrine:database:create --env=test","code":14} []
[2025-03-07T08:02:55.364911+00:00] doctrine.INFO: Connecting with parameters array{"use_savepoints":true,"driver":"pdo_sqlite","path":"%kernel.project_dir%/var/test.db","memory":false,"idle_connection_ttl":600,"host":"localhost","port":null,"user":"root","password":null,"driverOptions":[],"defaultTableOptions":[],"charset":"utf8"} {"params":{"use_savepoints":true,"driver":"pdo_sqlite","path":"%kernel.project_dir%/var/test.db","memory":false,"idle_connection_ttl":600,"host":"localhost","port":null,"user":"root","password":null,"driverOptions":[],"defaultTableOptions":[],"charset":"utf8"}} []
[2025-03-07T08:02:55.453015+00:00] console.CRITICAL: Error thrown while running command "doctrine:migrations:status --env=test". Message: "An exception occurred in the driver: SQLSTATE[HY000] [14] unable to open database file" {"exception":"[object] (Doctrine\\DBAL\\Exception\\ConnectionException(code: 14): An exception occurred in the driver: SQLSTATE[HY000] [14] unable to open database file at /mnt/c/Users/CDAX27/covoiturage/vendor/doctrine/dbal/src/Driver/API/SQLite/ExceptionConverter.php:76)\n[previous exception] [object] (Doctrine\\DBAL\\Driver\\PDO\\Exception(code: 14): SQLSTATE[HY000] [14] unable to open database file at /mnt/c/Users/CDAX27/covoiturage/vendor/doctrine/dbal/src/Driver/PDO/Exception.php:24)\n[previous exception] [object] (PDOException(code: 14): SQLSTATE[HY000] [14] unable to open database file at /mnt/c/Users/CDAX27/covoiturage/vendor/doctrine/dbal/src/Driver/PDO/SQLite/Driver.php:43)","command":"doctrine:migrations:status --env=test","message":"An exception occurred in the driver: SQLSTATE[HY000] [14] unable to open database file"} []
[2025-03-07T08:02:55.479293+00:00] console.DEBUG: Command "doctrine:migrations:status --env=test" exited with code "14" {"command":"doctrine:migrations:status --env=test","code":14} []
[2025-03-07T08:03:23.951809+00:00] doctrine.INFO: Connecting with parameters array{"use_savepoints":true,"driver":"pdo_sqlite","path":"%kernel.project_dir%/var/test.db","memory":false,"idle_connection_ttl":600,"host":"localhost","port":null,"user":"root","password":null,"driverOptions":[],"defaultTableOptions":[],"charset":"utf8"} {"params":{"use_savepoints":true,"driver":"pdo_sqlite","path":"%kernel.project_dir%/var/test.db","memory":false,"idle_connection_ttl":600,"host":"localhost","port":null,"user":"root","password":null,"driverOptions":[],"defaultTableOptions":[],"charset":"utf8"}} []
[2025-03-07T08:03:24.036925+00:00] console.CRITICAL: Error thrown while running command "doctrine:migrations:diff --env=test". Message: "An exception occurred in the driver: SQLSTATE[HY000] [14] unable to open database file" {"exception":"[object] (Doctrine\\DBAL\\Exception\\ConnectionException(code: 14): An exception occurred in the driver: SQLSTATE[HY000] [14] unable to open database file at /mnt/c/Users/CDAX27/covoiturage/vendor/doctrine/dbal/src/Driver/API/SQLite/ExceptionConverter.php:76)\n[previous exception] [object] (Doctrine\\DBAL\\Driver\\PDO\\Exception(code: 14): SQLSTATE[HY000] [14] unable to open database file at /mnt/c/Users/CDAX27/covoiturage/vendor/doctrine/dbal/src/Driver/PDO/Exception.php:24)\n[previous exception] [object] (PDOException(code: 14): SQLSTATE[HY000] [14] unable to open database file at /mnt/c/Users/CDAX27/covoiturage/vendor/doctrine/dbal/src/Driver/PDO/SQLite/Driver.php:43)","command":"doctrine:migrations:diff --env=test","message":"An exception occurred in the driver: SQLSTATE[HY000] [14] unable to open database file"} []
[2025-03-07T08:03:24.063777+00:00] console.DEBUG: Command "doctrine:migrations:diff --env=test" exited with code "14" {"command":"doctrine:migrations:diff --env=test","code":14} []
[2025-03-07T08:09:57.829516+00:00] doctrine.INFO: Connecting with parameters array{"use_savepoints":true,"driver":"pdo_sqlite","path":"%kernel.project_dir%/var/test.db","memory":false,"idle_connection_ttl":600,"host":"localhost","port":null,"user":"root","password":null,"driverOptions":[],"defaultTableOptions":[],"charset":"utf8"} {"params":{"use_savepoints":true,"driver":"pdo_sqlite","path":"%kernel.project_dir%/var/test.db","memory":false,"idle_connection_ttl":600,"host":"localhost","port":null,"user":"root","password":null,"driverOptions":[],"defaultTableOptions":[],"charset":"utf8"}} []
[2025-03-07T08:09:57.912882+00:00] console.CRITICAL: Error thrown while running command "doctrine:database:create --env=test". Message: "An exception occurred in the driver: SQLSTATE[HY000] [14] unable to open database file" {"exception":"[object] (Doctrine\\DBAL\\Exception\\ConnectionException(code: 14): An exception occurred in the driver: SQLSTATE[HY000] [14] unable to open database file at /mnt/c/Users/CDAX27/covoiturage/vendor/doctrine/dbal/src/Driver/API/SQLite/ExceptionConverter.php:76)\n[previous exception] [object] (Doctrine\\DBAL\\Driver\\PDO\\Exception(code: 14): SQLSTATE[HY000] [14] unable to open database file at /mnt/c/Users/CDAX27/covoiturage/vendor/doctrine/dbal/src/Driver/PDO/Exception.php:24)\n[previous exception] [object] (PDOException(code: 14): SQLSTATE[HY000] [14] unable to open database file at /mnt/c/Users/CDAX27/covoiturage/vendor/doctrine/dbal/src/Driver/PDO/SQLite/Driver.php:43)","command":"doctrine:database:create --env=test","message":"An exception occurred in the driver: SQLSTATE[HY000] [14] unable to open database file"} []
[2025-03-07T08:09:57.938294+00:00] console.DEBUG: Command "doctrine:database:create --env=test" exited with code "14" {"command":"doctrine:database:create --env=test","code":14} []
[2025-03-07T09:10:22.468044+01:00] doctrine.INFO: Connecting with parameters array{"use_savepoints":true,"driver":"pdo_sqlite","path":"%kernel.project_dir%/var/test.db","memory":false,"idle_connection_ttl":600,"host":"localhost","port":null,"user":"root","password":null,"driverOptions":[],"defaultTableOptions":[],"charset":"utf8"} {"params":{"use_savepoints":true,"driver":"pdo_sqlite","path":"%kernel.project_dir%/var/test.db","memory":false,"idle_connection_ttl":600,"host":"localhost","port":null,"user":"root","password":null,"driverOptions":[],"defaultTableOptions":[],"charset":"utf8"}} []
[2025-03-07T09:10:22.496308+01:00] console.CRITICAL: Error thrown while running command "doctrine:database:create --env=test". Message: "An exception occurred in the driver: SQLSTATE[HY000] [14] unable to open database file" {"exception":"[object] (Doctrine\\DBAL\\Exception\\ConnectionException(code: 14): An exception occurred in the driver: SQLSTATE[HY000] [14] unable to open database file at C:\\Users\\CDAX27\\covoiturage\\vendor\\doctrine\\dbal\\src\\Driver\\API\\SQLite\\ExceptionConverter.php:76)\n[previous exception] [object] (Doctrine\\DBAL\\Driver\\PDO\\Exception(code: 14): SQLSTATE[HY000] [14] unable to open database file at C:\\Users\\CDAX27\\covoiturage\\vendor\\doctrine\\dbal\\src\\Driver\\PDO\\Exception.php:24)\n[previous exception] [object] (PDOException(code: 14): SQLSTATE[HY000] [14] unable to open database file at C:\\Users\\CDAX27\\covoiturage\\vendor\\doctrine\\dbal\\src\\Driver\\PDO\\SQLite\\Driver.php:43)","command":"doctrine:database:create --env=test","message":"An exception occurred in the driver: SQLSTATE[HY000] [14] unable to open database file"} []
[2025-03-07T09:10:22.505392+01:00] console.DEBUG: Command "doctrine:database:create --env=test" exited with code "14" {"command":"doctrine:database:create --env=test","code":14} []
[2025-03-07T08:11:35.564530+00:00] doctrine.INFO: Connecting with parameters array{"use_savepoints":true,"driver":"pdo_sqlite","path":"%kernel.project_dir%/var/test.db","memory":false,"idle_connection_ttl":600,"host":"localhost","port":null,"user":"root","password":null,"driverOptions":[],"defaultTableOptions":[],"charset":"utf8"} {"params":{"use_savepoints":true,"driver":"pdo_sqlite","path":"%kernel.project_dir%/var/test.db","memory":false,"idle_connection_ttl":600,"host":"localhost","port":null,"user":"root","password":null,"driverOptions":[],"defaultTableOptions":[],"charset":"utf8"}} []
[2025-03-07T08:11:35.647539+00:00] console.CRITICAL: Error thrown while running command "doctrine:migrations:migrate --no-interaction --env=test". Message: "An exception occurred in the driver: SQLSTATE[HY000] [14] unable to open database file" {"exception":"[object] (Doctrine\\DBAL\\Exception\\ConnectionException(code: 14): An exception occurred in the driver: SQLSTATE[HY000] [14] unable to open database file at /mnt/c/Users/CDAX27/covoiturage/vendor/doctrine/dbal/src/Driver/API/SQLite/ExceptionConverter.php:76)\n[previous exception] [object] (Doctrine\\DBAL\\Driver\\PDO\\Exception(code: 14): SQLSTATE[HY000] [14] unable to open database file at /mnt/c/Users/CDAX27/covoiturage/vendor/doctrine/dbal/src/Driver/PDO/Exception.php:24)\n[previous exception] [object] (PDOException(code: 14): SQLSTATE[HY000] [14] unable to open database file at /mnt/c/Users/CDAX27/covoiturage/vendor/doctrine/dbal/src/Driver/PDO/SQLite/Driver.php:43)","command":"doctrine:migrations:migrate --no-interaction --env=test","message":"An exception occurred in the driver: SQLSTATE[HY000] [14] unable to open database file"} []
[2025-03-07T08:11:35.697203+00:00] console.DEBUG: Command "doctrine:migrations:migrate --no-interaction --env=test" exited with code "14" {"command":"doctrine:migrations:migrate --no-interaction --env=test","code":14} []
[2025-03-07T08:15:42.139134+00:00] doctrine.INFO: Connecting with parameters array{"use_savepoints":true,"driver":"pdo_sqlite","path":"%kernel.project_dir%/var/test.db","memory":false,"idle_connection_ttl":600,"host":"localhost","port":null,"user":"root","password":null,"driverOptions":[],"defaultTableOptions":[],"charset":"utf8"} {"params":{"use_savepoints":true,"driver":"pdo_sqlite","path":"%kernel.project_dir%/var/test.db","memory":false,"idle_connection_ttl":600,"host":"localhost","port":null,"user":"root","password":null,"driverOptions":[],"defaultTableOptions":[],"charset":"utf8"}} []
[2025-03-07T08:15:42.220717+00:00] console.CRITICAL: Error thrown while running command "doctrine:migrations:migrate --no-interaction --env=test". Message: "An exception occurred in the driver: SQLSTATE[HY000] [14] unable to open database file" {"exception":"[object] (Doctrine\\DBAL\\Exception\\ConnectionException(code: 14): An exception occurred in the driver: SQLSTATE[HY000] [14] unable to open database file at /mnt/c/Users/CDAX27/covoiturage/vendor/doctrine/dbal/src/Driver/API/SQLite/ExceptionConverter.php:76)\n[previous exception] [object] (Doctrine\\DBAL\\Driver\\PDO\\Exception(code: 14): SQLSTATE[HY000] [14] unable to open database file at /mnt/c/Users/CDAX27/covoiturage/vendor/doctrine/dbal/src/Driver/PDO/Exception.php:24)\n[previous exception] [object] (PDOException(code: 14): SQLSTATE[HY000] [14] unable to open database file at /mnt/c/Users/CDAX27/covoiturage/vendor/doctrine/dbal/src/Driver/PDO/SQLite/Driver.php:43)","command":"doctrine:migrations:migrate --no-interaction --env=test","message":"An exception occurred in the driver: SQLSTATE[HY000] [14] unable to open database file"} []
[2025-03-07T08:15:42.245820+00:00] console.DEBUG: Command "doctrine:migrations:migrate --no-interaction --env=test" exited with code "14" {"command":"doctrine:migrations:migrate --no-interaction --env=test","code":14} []
[2025-03-07T08:20:00.842365+00:00] doctrine.INFO: Connecting with parameters array{"use_savepoints":true,"driver":"pdo_sqlite","path":"%kernel.project_dir%/var/test.db","memory":false,"idle_connection_ttl":600,"host":"localhost","port":null,"user":"root","password":null,"driverOptions":[],"defaultTableOptions":[],"charset":"utf8"} {"params":{"use_savepoints":true,"driver":"pdo_sqlite","path":"%kernel.project_dir%/var/test.db","memory":false,"idle_connection_ttl":600,"host":"localhost","port":null,"user":"root","password":null,"driverOptions":[],"defaultTableOptions":[],"charset":"utf8"}} []
[2025-03-07T08:20:01.074224+00:00] console.CRITICAL: Error thrown while running command "doctrine:database:create --env=test". Message: "An exception occurred in the driver: SQLSTATE[HY000] [14] unable to open database file" {"exception":"[object] (Doctrine\\DBAL\\Exception\\ConnectionException(code: 14): An exception occurred in the driver: SQLSTATE[HY000] [14] unable to open database file at /mnt/c/Users/CDAX27/covoiturage/vendor/doctrine/dbal/src/Driver/API/SQLite/ExceptionConverter.php:76)\n[previous exception] [object] (Doctrine\\DBAL\\Driver\\PDO\\Exception(code: 14): SQLSTATE[HY000] [14] unable to open database file at /mnt/c/Users/CDAX27/covoiturage/vendor/doctrine/dbal/src/Driver/PDO/Exception.php:24)\n[previous exception] [object] (PDOException(code: 14): SQLSTATE[HY000] [14] unable to open database file at /mnt/c/Users/CDAX27/covoiturage/vendor/doctrine/dbal/src/Driver/PDO/SQLite/Driver.php:43)","command":"doctrine:database:create --env=test","message":"An exception occurred in the driver: SQLSTATE[HY000] [14] unable to open database file"} []
[2025-03-07T08:20:01.126734+00:00] console.DEBUG: Command "doctrine:database:create --env=test" exited with code "14" {"command":"doctrine:database:create --env=test","code":14} []
[2025-03-07T08:26:28.821554+00:00] doctrine.INFO: Connecting with parameters array{"use_savepoints":true,"driver":"pdo_sqlite","path":"%kernel.project_dir%/var/test.db","memory":false,"idle_connection_ttl":600,"host":"localhost","port":null,"user":"root","password":null,"driverOptions":[],"defaultTableOptions":[],"charset":"utf8"} {"params":{"use_savepoints":true,"driver":"pdo_sqlite","path":"%kernel.project_dir%/var/test.db","memory":false,"idle_connection_ttl":600,"host":"localhost","port":null,"user":"root","password":null,"driverOptions":[],"defaultTableOptions":[],"charset":"utf8"}} []
[2025-03-07T08:26:28.960382+00:00] console.CRITICAL: Error thrown while running command "doctrine:database:create --env=test". Message: "An exception occurred in the driver: SQLSTATE[HY000] [14] unable to open database file" {"exception":"[object] (Doctrine\\DBAL\\Exception\\ConnectionException(code: 14): An exception occurred in the driver: SQLSTATE[HY000] [14] unable to open database file at /mnt/c/Users/CDAX27/covoiturage/vendor/doctrine/dbal/src/Driver/API/SQLite/ExceptionConverter.php:76)\n[previous exception] [object] (Doctrine\\DBAL\\Driver\\PDO\\Exception(code: 14): SQLSTATE[HY000] [14] unable to open database file at /mnt/c/Users/CDAX27/covoiturage/vendor/doctrine/dbal/src/Driver/PDO/Exception.php:24)\n[previous exception] [object] (PDOException(code: 14): SQLSTATE[HY000] [14] unable to open database file at /mnt/c/Users/CDAX27/covoiturage/vendor/doctrine/dbal/src/Driver/PDO/SQLite/Driver.php:43)","command":"doctrine:database:create --env=test","message":"An exception occurred in the driver: SQLSTATE[HY000] [14] unable to open database file"} []
[2025-03-07T08:26:28.999901+00:00] console.DEBUG: Command "doctrine:database:create --env=test" exited with code "14" {"command":"doctrine:database:create --env=test","code":14} []
